Workbook
Name A: #REF!
Name A: #REF!
Name A: #REF!
Name A: #REF!
Name A: #REF!
Name A: #REF!
Name A: #REF!
Name A: #REF!
Name A: #REF!
Name A: #REF!
Name A: #REF!
Name A: #REF!
Name a??u55_Click: [1]!a??u55_Click
Name aa: #REF!
Name aa: #REF!
Name aa: #REF!
Name aa: #REF!
Name aa: #REF!
Name aa: #REF!
Name aa: #REF!
Name aa: #REF!
Name aa: #REF!
Name aa: #REF!
Name aa: #REF!
Name aa: #REF!
Name abc: #REF!
Name abc: #REF!
Name abc: #REF!
Name abc: #REF!
Name abc: #REF!
Name abc: #REF!
Name abc: #REF!
Name abc: #REF!
Name abc: #REF!
Name abc: #REF!
Name abc: #REF!
Name abc: #REF!
Name add: #REF!
Name add: #REF!
Name add: #REF!
Name add: #REF!
Name add: #REF!
Name add: #REF!
Name add: #REF!
Name add: #REF!
Name add: #REF!
Name add: #REF!
Name add: #REF!
Name add: #REF!
Name added: #REF!
Name added: #REF!
Name added: #REF!
Name added: #REF!
Name added: #REF!
Name added: #REF!
Name added: #REF!
Name added: #REF!
Name added: #REF!
Name added: #REF!
Name added: #REF!

Sheet Summary
B3: CUTTING + PREPERATION
B6: Cell | C6: Working Period | D6: STD MP | E6: ACT MP | F6: Gap | G6: Output | H6: Hari ke- | AO6: Day
H7: 1 | I7: 2 | J7: 3 | K7: 4 | L7: 5 | M7: =1+L7 -> 6 | N7: =1+M7 -> 7 | O7: =1+N7 -> 8 | P7: =1+O7 -> 9 | Q7: =1+P7 -> 10 | R7: =1+Q7 -> 11 | S7: =1+R7 -> 12 | T7: =1+S7 -> 13 | ... DE7: =1+DD7 -> 102 | DF7: =1+BF7 -> 52 | DG7: =1+DF7 -> 53 | DH7: =1+DG7 -> 54 | DI7: =1+DH7 -> 55 | DJ7: =1+DI7 -> 56 | DK7: =1+DJ7 -> 57 | DL7: =1+DK7 -> 58 | DM7: =1+DL7 -> 59 | DN7: =1+DM7 -> 60 | ... EC7: =1+EB7 -> 75
H8: 46013 | I8: 46014 | J8: 46015 | K8: 46017 | L8: 46020 | M8: 46021 | N8: 46022 | O8: 46024 | P8: 46027 | Q8: 46028 | R8: 46029 | S8: 46030 | T8: 46031 | U8: 46034 | V8: 46035 | W8: 46036 | X8: 46037 | Y8: 46039 | Z8: 46041 | AA8: 46042 | AB8: 46043 | AC8: 46044 | AD8: 46045 | AE8: 46048 | AF8: 46049 | AG8: 46050 | AH8: 46051 | AI8: 46052 | AJ8: 46055 | AK8: 46056 | AL8: 46057 | AM8: 46058 | AN8: 46059 | AO8: 46083 | AP8: 46084 | AQ8: 46085 | AR8: 46086 | AS8: 46087 | AT8: 46090 | AU8: 46091 | AV8: 46092 | AW8: 46093 | AX8: 46094 | AY8: 46097 | AZ8: 46098 | BA8: 46099 | BB8: 46106 | BC8: 46107 | BD8: 46108 | BE8: 46109 | BF8: 46111 | BG8: 45747 | BH8: 46113 | BI8: 46114 | BJ8: 46115 | BK8: 46116 | BL8: 46118 | BM8: 46119 | BN8: 46120 | BO8: 46121 | BP8: 46122 | BQ8: 46123 | BR8: 46125 | BS8: 46126 | BT8: 46127 | BU8: 46128 | BV8: 46129 | BW8: 46130 | BX8: 46132 | BY8: 46133 | BZ8: 46134 | CA8: 46135 | CB8: 46136 | CC8: 46137 | CD8: 46138 | CE8: 46139 | CF8: 46140 | CG8: 46141 | CH8: 46142 | CI8: 46143 | CJ8: 46144 | CK8: 46145 | CL8: 45778 | CM8: 45779 | CN8: 45780 | CO8: 45781 | CP8: 45782 | CQ8: 45783 | CR8: 45784 | CS8: 45785 | CT8: 45786 | CU8: 45787 | CV8: 45788 | CW8: 45789 | CX8: 45790 | CY8: 45791 | CZ8: 45792 | DA8: 45793 | DB8: 45794 | DC8: 45795 | DD8: 45796 | DE8: 45797 | DF8: 45798 | DG8: 45799 | DH8: 45800 | DI8: 45801 | DJ8: 45802 | DK8: 45803 | DL8: 45804 | DM8: 45805 | DN8: 45806 | DO8: 45807 | DP8: 45808 | DQ8: 45809 | DR8: 45810 | DS8: 45811 | DT8: 45812 | DU8: 45813 | DV8: 45814 | DW8: 45815 | DX8: 45816 | DY8: 45817 | DZ8: 45818 | EA8: 45819 | EB8: 45820 | EC8: 45821
B9: Cell 3 | C9: < 1 Month | D9: 27 | E9: 17 | F9: =+E9-D9:D9 -> -10 | G9: Output/Day | H9: 126 | I9: 150 | J9: 144 | L9: 222 | M9: 246 | N9: 216 | O9: 246 | P9: 246 | Q9: 288 | R9: 342 | AE9: 528 | AF9: 566 | AG9: 467 | AH9: 442 | AI9: 449 | AJ9: 583 | AK9: 692 | AL9: 714 | AM9: 774 | AN9: 798 | AO9: =+'Cell 5 603'!AS5 -> 0 | AP9: =+'Cell 5 603'!AT5 -> 0 | AQ9: =+'Cell 5 603'!AU5 -> 0 | AR9: =+'Cell 5 603'!AV5 -> 0 | AS9: =+'Cell 5 603'!AW5 -> 0 | AT9: =+'Cell 5 603'!AX5 -> 0 | AU9: =+'Cell 5 603'!AY5 -> 0 | AV9: =+'Cell 5 603'!AZ5 -> 0 | ... BE9: =+'Cell 5 603'!BI5 -> 0 | BJ9: =+'Cell 3 603'!D9 -> 642 | BK9: =+'Cell 3 603'!E9 -> 0 | BL9: =+'Cell 3 603'!F9 -> 282 | BM9: =+'Cell 3 603'!G9 -> 0 | BN9: =+'Cell 3 603'!H9 -> 546 | BO9: =+'Cell 3 603'!I9 -> 0 | BP9: =+'Cell 3 603'!J9 -> 120 | BQ9: =+'Cell 3 603'!K9 -> 0 | ... BY9: =+'Cell 3 603'!S9 -> 500
G10: Output/H | H10: =H9/9 -> 14 | I10: =I9/9 -> 16.666667 | J10: =J9/10 -> 14.4 | K10: =K9/9 -> 0 | L10: =+L9/9 -> 24.666667 | M10: =+M9/9 -> 27.333333 | N10: =N9/10 -> 21.6 | O10: =O9/10 -> 24.6 | P10: =P9/10 -> 24.6 | Q10: =Q9/10 -> 28.8 | R10: =SUM(R9:R9)/8 -> 42.75 | S10: =S9/8 -> 0 | T10: =T9/8 -> 0 | U10: =U9/8 -> 0 | V10: =V9/8 -> 0 | W10: =W9/8 -> 0 | X10: =SUM(X9:X9)/8 -> 0 | Y10: =SUM(Y9:Y9)/8 -> 0 | Z10: =SUM(Z9:Z9)/8 -> 0 | AA10: =SUM(AA9:AA9)/8 -> 0 | AB10: =SUM(AB9:AB9)/8 -> 0 | AC10: =SUM(AC9:AC9)/8 -> 0 | AD10: =AD9/9 -> 0 | AE10: =AE9/9 -> 58.666667 | AF10: =AF9/9 -> 62.888889 | AG10: =AG9/10 -> 46.7 | AH10: =AH9/9 -> 49.111111 | AI10: =+AI9/9 -> 49.888889 | AJ10: =+AJ9/9 -> 64.777778 | AK10: =AK9/9 -> 76.888889 | AL10: =AL9/9 -> 79.333333 | AM10: =AM9/9 -> 86 | AN10: =AN9/9 -> 88.666667 | AO10: =+'Cell 5 603'!AS6 -> 0 | AP10: =+'Cell 5 603'!AT6 -> 0 | AQ10: =+'Cell 5 603'!AU6 -> 0 | AR10: =+'Cell 5 603'!AV6 -> 0 | AS10: =+'Cell 5 603'!AW6 -> 0 | AT10: =+'Cell 5 603'!AX6 -> 0 | AU10: =+'Cell 5 603'!AY6 -> 0 | AV10: =+'Cell 5 603'!AZ6 -> 0 | ... BE10: =+'Cell 5 603'!BI6 -> 0 | BJ10: =+'Cell 3 603'!D10 -> 80.25 | BK10: =+'Cell 3 603'!E10 -> 0 | BL10: =+'Cell 3 603'!F10 -> 28.2 | BM10: =+'Cell 3 603'!G10 -> 0 | BN10: =+'Cell 3 603'!H10 -> 68.25 | BO10: =+'Cell 3 603'!I10 -> 0 | BP10: =+'Cell 3 603'!J10 -> 12 | BQ10: =+'Cell 3 603'!K10 -> 0 | ... BY10: =+'Cell 3 603'!S10 -> 62.5
B11: Cell 4 | C11: 3 Month | D11: 27 | E11: 25 | F11: =+E11-D11:D11 -> -2 | G11: Output/Day | H11: 468 | I11: 522 | J11: 300 | L11: 276 | M11: 540 | N11: 444 | O11: 462 | P11: 600 | Q11: 582 | R11: 429 | AE11: 600 | AF11: 600 | AG11: 612 | AH11: 672 | AI11: 348 | AJ11: 468 | AK11: 552 | AL11: 316 | AM11: 503 | AN11: 690 | AO11: =+'Cell 4 603'!BB9 -> 1278 | AP11: =+'Cell 4 603'!BC9 -> 732 | AQ11: =+'Cell 4 603'!BD9 -> 660 | AR11: =+'Cell 4 603'!BE9 -> 600 | AS11: =+'Cell 4 603'!BF9 -> 0 | AT11: =+'Cell 4 603'!BG9 -> 0 | AU11: =+'Cell 4 603'!BH9 -> 708 | AV11: =+'Cell 4 603'!BI9 -> 600 | ... BY11: =+'Cell 4 603'!CL9 -> 1068
G12: Output/H | H12: =H11/8 -> 58.5 | I12: =I11/8 -> 65.25 | J12: =J11/10 -> 30 | K12: =K11/8 -> 0 | L12: =+L11/8 -> 34.5 | M12: =+M11/8 -> 67.5 | N12: =N11/10 -> 44.4 | O12: =O11/10 -> 46.2 | P12: =P11/10 -> 60 | Q12: =Q11/10 -> 58.2 | R12: =SUM(R11:R11)/8 -> 53.625 | S12: =S11/8 -> 0 | T12: =T11/8 -> 0 | U12: =U11/8 -> 0 | V12: =V11/8 -> 0 | W12: =W11/8 -> 0 | X12: =SUM(X11:X11)/8 -> 0 | Y12: =SUM(Y11:Y11)/8 -> 0 | Z12: =SUM(Z11:Z11)/8 -> 0 | AA12: =SUM(AA11:AA11)/8 -> 0 | AB12: =SUM(AB11:AB11)/8 -> 0 | AC12: =SUM(AC11:AC11)/8 -> 0 | AD12: =AD11/8 -> 0 | AE12: =AE11/8 -> 75 | AF12: =AF11/8 -> 75 | AG12: =AG11/10 -> 61.2 | AH12: =AH11/8 -> 84 | AI12: =+AI11/8 -> 43.5 | AJ12: =+AJ11/8 -> 58.5 | AK12: =AK11/9 -> 61.333333 | AL12: =AL11/8 -> 39.5 | AM12: =AM11/8 -> 62.875 | AN12: =SUM(AN11:AN11)/8 -> 86.25 | AO12: =+'Cell 4 603'!BB10 -> 159.75 | AP12: =+'Cell 4 603'!BC10 -> 91.5 | AQ12: =+'Cell 4 603'!BD10 -> 82.5 | AR12: =+'Cell 4 603'!BE10 -> 75 | AS12: =+'Cell 4 603'!BF10 -> 0 | AT12: =+'Cell 4 603'!BG10 -> 0 | AU12: =+'Cell 4 603'!BH10 -> 88.5 | AV12: =+'Cell 4 603'!BI10 -> 75 | ... BY12: =+'Cell 4 603'!CL10 -> 89
B13: Cell 5 | C13: 3 Month | D13: 27 | E13: 26 | F13: =+E13-D13:D13 -> -1 | G13: =G11 -> Output/Day | H13: 126 | I13: 150 | J13: 144 | L13: 222 | M13: 246 | N13: 216 | O13: 246 | P13: 246 | Q13: 288 | R13: 342 | AE13: 528 | AF13: 566 | AG13: 467 | AH13: 442 | AI13: 449 | AJ13: 583 | AK13: 692 | AL13: 714 | AM13: 774 | AN13: 798 | AO13: =+'Cell 5 603'!AS9 -> 960 | AP13: =+'Cell 5 603'!AT9 -> 708 | AQ13: =+'Cell 5 603'!AU9 -> 540 | AR13: =+'Cell 5 603'!AV9 -> 462 | AS13: =+'Cell 5 603'!AW9 -> 222 | AT13: =+'Cell 5 603'!AX9 -> 0 | AU13: =+'Cell 5 603'!AY9 -> 0 | AV13: =+'Cell 5 603'!AZ9 -> 584 | ... BY13: =+'Cell 5 603'!CC9 -> 2292
G14: Output/H | H14: =H13/9 -> 14 | I14: =I13/9 -> 16.666667 | J14: =J13/10 -> 14.4 | K14: =K13/9 -> 0 | L14: =+L13/9 -> 24.666667 | M14: =+M13/9 -> 27.333333 | N14: =N13/10 -> 21.6 | O14: =O13/10 -> 24.6 | P14: =P13/10 -> 24.6 | Q14: =Q13/10 -> 28.8 | R14: =SUM(R13:R13)/8 -> 42.75 | S14: =S13/8 -> 0 | T14: =T13/8 -> 0 | U14: =U13/8 -> 0 | V14: =V13/8 -> 0 | W14: =W13/8 -> 0 | X14: =SUM(X13:X13)/8 -> 0 | Y14: =SUM(Y13:Y13)/8 -> 0 | Z14: =SUM(Z13:Z13)/8 -> 0 | AA14: =SUM(AA13:AA13)/8 -> 0 | AB14: =SUM(AB13:AB13)/8 -> 0 | AC14: =SUM(AC13:AC13)/8 -> 0 | AD14: =AD13/9 -> 0 | AE14: =AE13/9 -> 58.666667 | AF14: =AF13/9 -> 62.888889 | AG14: =AG13/10 -> 46.7 | AH14: =AH13/9 -> 49.111111 | AI14: =+AI13/9 -> 49.888889 | AJ14: =+AJ13/9 -> 64.777778 | AK14: =AK13/9 -> 76.888889 | AL14: =AL13/9 -> 79.333333 | AM14: =AM13/9 -> 86 | AN14: =AN13/9 -> 88.666667 | AO14: =+'Cell 5 603'!AS10 -> 106.66667 | AP14: =+'Cell 5 603'!AT10 -> 88.5 | AQ14: =+'Cell 5 603'!AU10 -> 67.5 | AR14: =+'Cell 5 603'!AV10 -> 57.75 | AS14: =+'Cell 5 603'!AW10 -> 27.75 | AT14: =+'Cell 5 603'!AX10 -> 0 | AU14: =+'Cell 5 603'!AY10 -> 0 | AV14: =+'Cell 5 603'!AZ10 -> 64.888889 | ... BY14: =+'Cell 5 603'!CC10 -> 191
B15: Cell 9 | C15: < 1 Month | D15: 27 | E15: 22 | F15: =+E15-D15:D15 -> -5 | G15: Output/Day | H15: 468 | I15: 522 | J15: 300 | L15: 276 | M15: 540 | N15: 444 | O15: 462 | P15: 600 | Q15: 582 | R15: 429 | AE15: 600 | AF15: 600 | AG15: 612 | AH15: 672 | AI15: 348 | AJ15: 468 | AK15: 552 | AL15: 316 | AM15: 503 | AN15: 690 | AO15: =+'Cell 4 603'!BB13 -> 636 | AP15: =+'Cell 4 603'!BC13 -> 702 | AQ15: =+'Cell 4 603'!BD13 -> 630 | AR15: =+'Cell 4 603'!BE13 -> 546 | AS15: =+'Cell 4 603'!BF13 -> 540 | AT15: =+'Cell 4 603'!BG13 -> 510 | AU15: =+'Cell 4 603'!BH13 -> 600 | AV15: =+'Cell 4 603'!BI13 -> 600 | ... BE15: =+'Cell 4 603'!BR13 -> 810 | BJ15: =+'Cell 9 603'!F9 -> 1074 | BK15: =+'Cell 9 603'!G9 -> 576 | BL15: =+'Cell 9 603'!H9 -> 84 | BM15: =+'Cell 9 603'!I9 -> 240 | BN15: =+'Cell 9 603'!J9 -> 228 | BO15: =+'Cell 9 603'!K9 -> 198 | BP15: =+'Cell 9 603'!L9 -> 222 | BQ15: =+'Cell 9 603'!M9 -> 222 | ... BY15: =+'Cell 9 603'!U9 -> 762
G16: Output/H | H16: =H15/8 -> 58.5 | I16: =I15/8 -> 65.25 | J16: =J15/10 -> 30 | K16: =K15/8 -> 0 | L16: =+L15/8 -> 34.5 | M16: =+M15/8 -> 67.5 | N16: =N15/10 -> 44.4 | O16: =O15/10 -> 46.2 | P16: =P15/10 -> 60 | Q16: =Q15/10 -> 58.2 | R16: =SUM(R15:R15)/8 -> 53.625 | S16: =S15/8 -> 0 | T16: =T15/8 -> 0 | U16: =U15/8 -> 0 | V16: =V15/8 -> 0 | W16: =W15/8 -> 0 | X16: =SUM(X15:X15)/8 -> 0 | Y16: =SUM(Y15:Y15)/8 -> 0 | Z16: =SUM(Z15:Z15)/8 -> 0 | AA16: =SUM(AA15:AA15)/8 -> 0 | AB16: =SUM(AB15:AB15)/8 -> 0 | AC16: =SUM(AC15:AC15)/8 -> 0 | AD16: =AD15/8 -> 0 | AE16: =AE15/8 -> 75 | AF16: =AF15/8 -> 75 | AG16: =AG15/10 -> 61.2 | AH16: =AH15/8 -> 84 | AI16: =+AI15/8 -> 43.5 | AJ16: =+AJ15/8 -> 58.5 | AK16: =AK15/9 -> 61.333333 | AL16: =AL15/8 -> 39.5 | AM16: =AM15/8 -> 62.875 | AN16: =SUM(AN15:AN15)/8 -> 86.25 | AO16: =+'Cell 4 603'!BB14 -> 63.6 | AP16: =+'Cell 4 603'!BC14 -> 70.2 | AQ16: =+'Cell 4 603'!BD14 -> 63 | AR16: =+'Cell 4 603'!BE14 -> 54.6 | AS16: =+'Cell 4 603'!BF14 -> 54 | AT16: =+'Cell 4 603'!BG14 -> 51 | AU16: =+'Cell 4 603'!BH14 -> 60 | AV16: =+'Cell 4 603'!BI14 -> 60 | ... BE16: =+'Cell 4 603'!BR14 -> 81 | BJ16: =+'Cell 9 603'!F10 -> 107.4 | BK16: =+'Cell 9 603'!G10 -> 57.6 | BL16: =+'Cell 9 603'!H10 -> 8.4 | BM16: =+'Cell 9 603'!I10 -> 30 | BN16: =+'Cell 9 603'!J10 -> 28.5 | BO16: =+'Cell 9 603'!K10 -> 24.75 | BP16: =+'Cell 9 603'!L10 -> 27.75 | BQ16: =+'Cell 9 603'!M10 -> 27.75 | ... BY16: =+'Cell 9 603'!U10 -> 95.25
B17: Cell 10 | C17: 2 Month | D17: 27 | E17: 25 | F17: =+E17-D17:D17 -> -2 | G17: =G11 -> Output/Day | H17: 72 | I17: 126 | J17: 150 | L17: 107 | M17: 270 | N17: 180 | O17: 246 | P17: 342 | Q17: 402 | R17: 420 | AE17: 541 | AF17: 600 | AG17: 504 | AH17: 722 | AI17: 504 | AJ17: 540 | AK17: 612 | AL17: 703 | AM17: 774 | AN17: 800 | AO17: =+'Cell 10 603'!AI9 -> 636 | AP17: =+'Cell 10 603'!AJ9 -> 456 | AQ17: =+'Cell 10 603'!AK9 -> 504 | AR17: =+'Cell 10 603'!AL9 -> 0 | AS17: =+'Cell 10 603'!AM9 -> 0 | AT17: =+'Cell 10 603'!AN9 -> 504 | AU17: =+'Cell 10 603'!AO9 -> 504 | AV17: =+'Cell 10 603'!AP9 -> 708 | ... BY17: =+'Cell 10 603'!BS9 -> 870
G18: Output/H | H18: =H17/9 -> 8 | I18: =I17/9 -> 14 | J18: =J17/9 -> 16.666667 | K18: =K17/9 -> 0 | L18: =+L17/9 -> 11.888889 | M18: =+M17/9 -> 30 | N18: =N17/9 -> 20 | O18: =O17/9 -> 27.333333 | P18: =P17/9 -> 38 | Q18: =Q17/9 -> 44.666667 | R18: =SUM(R17:R17)/8 -> 52.5 | S18: =S17/8 -> 0 | T18: =T17/8 -> 0 | U18: =U17/8 -> 0 | V18: =V17/8 -> 0 | W18: =W17/8 -> 0 | X18: =SUM(X17:X17)/8 -> 0 | Y18: =SUM(Y17:Y17)/8 -> 0 | Z18: =SUM(Z17:Z17)/8 -> 0 | AA18: =SUM(AA17:AA17)/8 -> 0 | AB18: =SUM(AB17:AB17)/8 -> 0 | AC18: =SUM(AC17:AC17)/8 -> 0 | AD18: =AD17/9 -> 0 | AE18: =AE17/9 -> 60.111111 | AF18: =AF17/9 -> 66.666667 | AG18: =AG17/9 -> 56 | AH18: =AH17/9 -> 80.222222 | AI18: =+AI17/9 -> 56 | AJ18: =+AJ17/9 -> 60 | AK18: =AK17/9 -> 68 | AL18: =AL17/9 -> 78.111111 | AM18: =AM17/9 -> 86 | AN18: =AN17/9 -> 88.888889 | AO18: =+'Cell 10 603'!AI10 -> 79.5 | AP18: =+'Cell 10 603'!AJ10 -> 57 | AQ18: =+'Cell 10 603'!AK10 -> 63 | AR18: =+'Cell 10 603'!AL10 -> 0 | AS18: =+'Cell 10 603'!AM10 -> 0 | AT18: =+'Cell 10 603'!AN10 -> 63 | AU18: =+'Cell 10 603'!AO10 -> 63 | AV18: =+'Cell 10 603'!AP10 -> 88.5 | ... BY18: =+'Cell 10 603'!BS10 -> 72.5
B19: Cell 11 | C19: 1 Month | D19: 27 | E19: 19 | F19: =+E19-D19:D19 -> -8 | G19: =G17 -> Output/Day | H19: 126 | I19: 150 | J19: 144 | L19: 222 | M19: 246 | N19: 216 | O19: 246 | P19: 246 | Q19: 288 | R19: 342 | AE19: 528 | AF19: 566 | AG19: 467 | AH19: 442 | AI19: 449 | AJ19: 583 | AK19: 692 | AL19: 714 | AM19: 774 | AN19: 798 | AO19: =+'Cell 5 603'!AS13 -> 840 | AP19: =+'Cell 5 603'!AT13 -> 702 | AQ19: =+'Cell 5 603'!AU13 -> 702 | AR19: =+'Cell 5 603'!AV13 -> 702 | AS19: =+'Cell 5 603'!AW13 -> 630 | AT19: =+'Cell 5 603'!AX13 -> 804 | AU19: =+'Cell 5 603'!AY13 -> 726 | AV19: =+'Cell 5 603'!AZ13 -> 450 | ... BF19: =+'Cell 5 603'!BJ13 -> 803 | BG19: =+'Cell 11 603'!W9 -> 960 | BH19: =+'Cell 11 603'!X9 -> 954 | BI19: =+'Cell 11 603'!Y9 -> 624 | BJ19: =+'Cell 11 603'!Z9 -> 1126 | BK19: =+'Cell 11 603'!AA9 -> 804 | BL19: =+'Cell 11 603'!AB9 -> 222 | BM19: =+'Cell 11 603'!AC9 -> 948 | BN19: =+'Cell 11 603'!AD9 -> 1032 | ... BY19: =+'Cell 11 603'!AO9 -> 1680
G20: Output/H | H20: =H19/9 -> 14 | I20: =I19/9 -> 16.666667 | J20: =J19/10 -> 14.4 | K20: =K19/9 -> 0 | L20: =+L19/9 -> 24.666667 | M20: =+M19/9 -> 27.333333 | N20: =N19/10 -> 21.6 | O20: =O19/10 -> 24.6 | P20: =P19/10 -> 24.6 | Q20: =Q19/10 -> 28.8 | R20: =SUM(R19:R19)/8 -> 42.75 | S20: =S19/8 -> 0 | T20: =T19/8 -> 0 | U20: =U19/8 -> 0 | V20: =V19/8 -> 0 | W20: =W19/8 -> 0 | X20: =SUM(X19:X19)/8 -> 0 | Y20: =SUM(Y19:Y19)/8 -> 0 | Z20: =SUM(Z19:Z19)/8 -> 0 | AA20: =SUM(AA19:AA19)/8 -> 0 | AB20: =SUM(AB19:AB19)/8 -> 0 | AC20: =SUM(AC19:AC19)/8 -> 0 | AD20: =AD19/9 -> 0 | AE20: =AE19/9 -> 58.666667 | AF20: =AF19/9 -> 62.888889 | AG20: =AG19/10 -> 46.7 | AH20: =AH19/9 -> 49.111111 | AI20: =+AI19/9 -> 49.888889 | AJ20: =+AJ19/9 -> 64.777778 | AK20: =AK19/9 -> 76.888889 | AL20: =AL19/9 -> 79.333333 | AM20: =AM19/9 -> 86 | AN20: =AN19/9 -> 88.666667 | AO20: =+'Cell 5 603'!AS14 -> 84 | AP20: =+'Cell 5 603'!AT14 -> 70.2 | AQ20: =+'Cell 5 603'!AU14 -> 70.2 | AR20: =+'Cell 5 603'!AV14 -> 70.2 | AS20: =+'Cell 5 603'!AW14 -> 63 | AT20: =+'Cell 5 603'!AX14 -> 80.4 | AU20: =+'Cell 5 603'!AY14 -> 72.6 | AV20: =+'Cell 5 603'!AZ14 -> 45 | ... BF20: =+'Cell 5 603'!BJ14 -> 73 | BG20: =+'Cell 11 603'!W10 -> 96 | BH20: =+'Cell 11 603'!X10 -> 95.4 | BI20: =+'Cell 11 603'!Y10 -> 62.4 | BJ20: =+'Cell 11 603'!Z10 -> 112.6 | BK20: =+'Cell 11 603'!AA10 -> 80.4 | BL20: =+'Cell 11 603'!AB10 -> 22.2 | BM20: =+'Cell 11 603'!AC10 -> 79 | BN20: =+'Cell 11 603'!AD10 -> 86 | ... BY20: =+'Cell 11 603'!AO10 -> 168
B21: TARGET RUMP UP LEAN | H21: 12 | I21: 12 | J21: 12 | K21: 12 | L21: 12 | M21: 24 | N21: 24 | O21: 24 | P21: 24 | Q21: 24 | R21: 48 | S21: 48 | T21: 48 | U21: 48 | V21: 48 | W21: 60 | X21: 60 | Y21: 60 | Z21: 60 | AA21: 60 | AB21: 72 | AC21: 72 | AD21: 72 | AE21: 72 | AF21: 72 | AG21: 96 | AH21: 96 | AI21: 96 | AJ21: 96 | AK21: 96 | AL21: 108 | AM21: 108 | AN21: 108 | AO21: 120 | AP21: 120 | AQ21: 120 | AR21: 120 | AS21: 120 | AT21: 120 | AU21: 120 | AV21: 120 | AW21: 120 | AX21: 120 | AY21: 120 | AZ21: 120 | BA21: 120 | BB21: 120 | BC21: 120 | BD21: 120 | BE21: 120 | BF21: 120 | BG21: 120 | BH21: 120 | BI21: 120 | BJ21: 120 | BK21: 120 | BL21: 120 | BM21: 120 | BN21: 120 | BO21: 120 | BP21: 120 | BQ21: 120 | BR21: 120 | BS21: 120 | BT21: 120 | BU21: 120 | BV21: 120 | BW21: 120 | BX21: 120 | BY21: 120 | BZ21: 120 | CA21: 120 | CB21: 120 | CC21: 120 | CD21: 120 | CE21: 120 | CF21: 120 | CG21: 120 | CH21: 120 | CI21: 120 | CJ21: 120 | CK21: 120 | CL21: 108 | CM21: 108 | CN21: 120 | CO21: 120 | CP21: 120 | CQ21: 120 | CR21: 120 | CS21: 120 | CT21: 120 | CU21: 120 | CV21: 120 | CW21: 120 | CX21: 120 | CY21: 120 | CZ21: 120 | DA21: 120 | DB21: 120 | DC21: 120 | DD21: 120 | DE21: 120 | DF21: 120 | DG21: 120 | DH21: 120 | DI21: 120 | DJ21: 120 | DK21: 120 | DL21: 120 | DM21: 120 | DN21: 120 | DO21: 120 | DP21: 120 | DQ21: 120 | DR21: 120 | DS21: 120 | DT21: 120 | DU21: 120 | DV21: 120 | DW21: 120 | DX21: 120 | DY21: 120 | DZ21: 120 | EA21: 120 | EB21: 120 | EC21: 120
B24: COMPUTER STITCHING
B27: Cell | C27: Working Period | D27: STD MP | E27: ACT MP | F27: Gap | G27: Output | H27: Hari ke- | AO27: Day
H28: 1 | I28: 2 | J28: 3 | K28: 4 | L28: 5 | M28: =1+L28 -> 6 | N28: =1+M28 -> 7 | O28: =1+N28 -> 8 | P28: =1+O28 -> 9 | Q28: =1+P28 -> 10 | R28: =1+Q28 -> 11 | S28: =1+R28 -> 12 | T28: =1+S28 -> 13 | ... DE28: =1+DD28 -> 102 | DF28: =1+BF28 -> 52 | DG28: =1+DF28 -> 53 | DH28: =1+DG28 -> 54 | DI28: =1+DH28 -> 55 | DJ28: =1+DI28 -> 56 | DK28: =1+DJ28 -> 57 | DL28: =1+DK28 -> 58 | DM28: =1+DL28 -> 59 | DN28: =1+DM28 -> 60 | ... EC28: =1+EB28 -> 75
H29: 46013 | I29: 46014 | J29: 46015 | K29: 46017 | L29: 46020 | M29: 46021 | N29: 46022 | O29: 46024 | P29: 46027 | Q29: 46028 | R29: 46029 | S29: 46030 | T29: 46031 | U29: 46034 | V29: 46035 | W29: 46036 | X29: 46037 | Y29: 46039 | Z29: 46041 | AA29: 46042 | AB29: 46043 | AC29: 46044 | AD29: 46045 | AE29: 46048 | AF29: 46049 | AG29: 46050 | AH29: 46051 | AI29: 46052 | AJ29: 46055 | AK29: 46056 | AL29: 46057 | AM29: 46058 | AN29: 46059 | AO29: 46083 | AP29: 46084 | AQ29: 46085 | AR29: 46086 | AS29: 46087 | AT29: 46090 | AU29: 46091 | AV29: 46092 | AW29: 46093 | AX29: 46094 | AY29: 46097 | AZ29: 46098 | BA29: 46099 | BB29: 46106 | BC29: 46107 | BD29: 46108 | BE29: 46109 | BF29: 46111 | BG29: 45747 | BH29: 46113 | BI29: 46114 | BJ29: 46115 | BK29: 46116 | BL29: 46118 | BM29: 46119 | BN29: 46120 | BO29: 46121 | BP29: 46122 | BQ29: 46123 | BR29: 46125 | BS29: 46126 | BT29: 46127 | BU29: 46128 | BV29: 46129 | BW29: 46130 | BX29: 46132 | BY29: 46133 | BZ29: 46134 | CA29: 46135 | CB29: 46136 | CC29: 46137 | CD29: 46138 | CE29: 46139 | CF29: 46140 | CG29: 46141 | CH29: 46142 | CI29: 46143 | CJ29: 46144 | CK29: 46145 | CL29: 45778 | CM29: 45779 | CN29: 45780 | CO29: 45781 | CP29: 45782 | CQ29: 45783 | CR29: 45784 | CS29: 45785 | CT29: 45786 | CU29: 45787 | CV29: 45788 | CW29: 45789 | CX29: 45790 | CY29: 45791 | CZ29: 45792 | DA29: 45793 | DB29: 45794 | DC29: 45795 | DD29: 45796 | DE29: 45797 | DF29: 45798 | DG29: 45799 | DH29: 45800 | DI29: 45801 | DJ29: 45802 | DK29: 45803 | DL29: 45804 | DM29: 45805 | DN29: 45806 | DO29: 45807 | DP29: 45808 | DQ29: 45809 | DR29: 45810 | DS29: 45811 | DT29: 45812 | DU29: 45813 | DV29: 45814 | DW29: 45815 | DX29: 45816 | DY29: 45817 | DZ29: 45818 | EA29: 45819 | EB29: 45820 | EC29: 45821
B30: Cell 4 | C30: 3 Month | D30: 35 | E30: 33 | F30: =+E30-D30 -> -2 | G30: Output/Day | H30: 468 | I30: 522 | J30: 300 | L30: 276 | M30: 540 | N30: 444 | O30: 462 | P30: 600 | Q30: 582 | R30: 429 | AE30: 600 | AF30: 600 | AG30: 612 | AH30: 672 | AI30: 348 | AJ30: 468 | AK30: 552 | AL30: 316 | AM30: 503 | AN30: 690 | AO30: =+'Cell 4 603'!BB11 -> 510 | AP30: =+'Cell 4 603'!BC11 -> 612 | AQ30: =+'Cell 4 603'!BD11 -> 580 | AR30: =+'Cell 4 603'!BE11 -> 568 | AS30: =+'Cell 4 603'!BF11 -> 568 | AT30: =+'Cell 4 603'!BG11 -> 480 | AU30: =+'Cell 4 603'!BH11 -> 516 | AV30: =+'Cell 4 603'!BI11 -> 600 | ... BY30: =+'Cell 4 603'!CL11 -> 916
G31: Output/H | H31: =H30/8 -> 58.5 | I31: =I30/8 -> 65.25 | J31: =J30/10 -> 30 | K31: =K30/8 -> 0 | L31: =+L30/8 -> 34.5 | M31: =+M30/8 -> 67.5 | N31: =N30/10 -> 44.4 | O31: =O30/10 -> 46.2 | P31: =P30/10 -> 60 | Q31: =Q30/10 -> 58.2 | R31: =SUM(R30:R30)/8 -> 53.625 | S31: =S30/8 -> 0 | T31: =T30/8 -> 0 | U31: =U30/8 -> 0 | V31: =V30/8 -> 0 | W31: =W30/8 -> 0 | X31: =SUM(X30:X30)/8 -> 0 | Y31: =SUM(Y30:Y30)/8 -> 0 | Z31: =SUM(Z30:Z30)/8 -> 0 | AA31: =SUM(AA30:AA30)/8 -> 0 | AB31: =SUM(AB30:AB30)/8 -> 0 | AC31: =SUM(AC30:AC30)/8 -> 0 | AD31: =AD30/8 -> 0 | AE31: =AE30/8 -> 75 | AF31: =AF30/8 -> 75 | AG31: =AG30/10 -> 61.2 | AH31: =AH30/8 -> 84 | AI31: =+AI30/8 -> 43.5 | AJ31: =+AJ30/8 -> 58.5 | AK31: =AK30/9 -> 61.333333 | AL31: =AL30/8 -> 39.5 | AM31: =AM30/8 -> 62.875 | AN31: =SUM(AN30:AN30)/8 -> 86.25 | AO31: =+'Cell 4 603'!BB12 -> 51 | AP31: =+'Cell 4 603'!BC12 -> 61.2 | AQ31: =+'Cell 4 603'!BD12 -> 58 | AR31: =+'Cell 4 603'!BE12 -> 56.8 | AS31: =+'Cell 4 603'!BF12 -> 56.8 | AT31: =+'Cell 4 603'!BG12 -> 48 | AU31: =+'Cell 4 603'!BH12 -> 51.6 | AV31: =+'Cell 4 603'!BI12 -> 60 | ... BY31: =+'Cell 4 603'!CL12 -> 76.333333
B32: Cell 5 | C32: 3 Month | D32: 35 | E32: 31 | F32: =+E32-D32 -> -4 | G32: =G30 -> Output/Day | H32: 126 | I32: 150 | J32: 144 | L32: 222 | M32: 246 | N32: 216 | O32: 246 | P32: 246 | Q32: 288 | R32: 342 | AE32: 528 | AF32: 566 | AG32: 467 | AH32: 442 | AI32: 449 | AJ32: 583 | AK32: 692 | AL32: 714 | AM32: 774 | AN32: 798 | AO32: =+'Cell 5 603'!AS11 -> 502 | AP32: =+'Cell 5 603'!AT11 -> 714 | AQ32: =+'Cell 5 603'!AU11 -> 573 | AR32: =+'Cell 5 603'!AV11 -> 562 | AS32: =+'Cell 5 603'!AW11 -> 603 | AT32: =+'Cell 5 603'!AX11 -> 780 | AU32: =+'Cell 5 603'!AY11 -> 570 | AV32: =+'Cell 5 603'!AZ11 -> 450 | ... BY32: =+'Cell 5 603'!CC11 -> 1000
G33: Output/H | H33: =H32/9 -> 14 | I33: =I32/9 -> 16.666667 | J33: =J32/10 -> 14.4 | K33: =K32/9 -> 0 | L33: =+L32/9 -> 24.666667 | M33: =+M32/9 -> 27.333333 | N33: =N32/10 -> 21.6 | O33: =O32/10 -> 24.6 | P33: =P32/10 -> 24.6 | Q33: =Q32/10 -> 28.8 | R33: =SUM(R32:R32)/8 -> 42.75 | S33: =S32/8 -> 0 | T33: =T32/8 -> 0 | U33: =U32/8 -> 0 | V33: =V32/8 -> 0 | W33: =W32/8 -> 0 | X33: =SUM(X32:X32)/8 -> 0 | Y33: =SUM(Y32:Y32)/8 -> 0 | Z33: =SUM(Z32:Z32)/8 -> 0 | AA33: =SUM(AA32:AA32)/8 -> 0 | AB33: =SUM(AB32:AB32)/8 -> 0 | AC33: =SUM(AC32:AC32)/8 -> 0 | AD33: =AD32/9 -> 0 | AE33: =AE32/9 -> 58.666667 | AF33: =AF32/9 -> 62.888889 | AG33: =AG32/10 -> 46.7 | AH33: =AH32/9 -> 49.111111 | AI33: =+AI32/9 -> 49.888889 | AJ33: =+AJ32/9 -> 64.777778 | AK33: =AK32/9 -> 76.888889 | AL33: =AL32/9 -> 79.333333 | AM33: =AM32/9 -> 86 | AN33: =AN32/9 -> 88.666667 | AO33: =+'Cell 5 603'!AS12 -> 50.2 | AP33: =+'Cell 5 603'!AT12 -> 71.4 | AQ33: =+'Cell 5 603'!AU12 -> 57.3 | AR33: =+'Cell 5 603'!AV12 -> 56.2 | AS33: =+'Cell 5 603'!AW12 -> 60.3 | AT33: =+'Cell 5 603'!AX12 -> 78 | AU33: =+'Cell 5 603'!AY12 -> 57 | AV33: =+'Cell 5 603'!AZ12 -> 45 | ... BY33: =+'Cell 5 603'!CC12 -> 83.333333
B34: Cell 10 | C34: 2 Month | D34: 35 | E34: 28 | F34: =+E34-D34 -> -7 | G34: =G30 -> Output/Day | H34: 72 | I34: 126 | J34: 150 | L34: 107 | M34: 270 | N34: 180 | O34: 246 | P34: 342 | Q34: 402 | R34: 420 | AE34: 541 | AF34: 600 | AG34: 504 | AH34: 722 | AI34: 504 | AJ34: 540 | AK34: 612 | AL34: 703 | AM34: 774 | AN34: 800 | AO34: =+'Cell 10 603'!AI11 -> 750 | AP34: =+'Cell 10 603'!AJ11 -> 777 | AQ34: =+'Cell 10 603'!AK11 -> 528 | AR34: =+'Cell 10 603'!AL11 -> 550 | AS34: =+'Cell 10 603'!AM11 -> 636 | AT34: =+'Cell 10 603'!AN11 -> 510 | AU34: =+'Cell 10 603'!AO11 -> 477 | AV34: =+'Cell 10 603'!AP11 -> 550 | ... BY34: =+'Cell 10 603'!BS11 -> 1680
G35: Output/H | H35: =H34/9 -> 8 | I35: =I34/9 -> 14 | J35: =J34/9 -> 16.666667 | K35: =K34/9 -> 0 | L35: =+L34/9 -> 11.888889 | M35: =+M34/9 -> 30 | N35: =N34/9 -> 20 | O35: =O34/9 -> 27.333333 | P35: =P34/9 -> 38 | Q35: =Q34/9 -> 44.666667 | R35: =SUM(R34:R34)/8 -> 52.5 | S35: =S34/8 -> 0 | T35: =T34/8 -> 0 | U35: =U34/8 -> 0 | V35: =V34/8 -> 0 | W35: =W34/8 -> 0 | X35: =SUM(X34:X34)/8 -> 0 | Y35: =SUM(Y34:Y34)/8 -> 0 | Z35: =SUM(Z34:Z34)/8 -> 0 | AA35: =SUM(AA34:AA34)/8 -> 0 | AB35: =SUM(AB34:AB34)/8 -> 0 | AC35: =SUM(AC34:AC34)/8 -> 0 | AD35: =AD34/9 -> 0 | AE35: =AE34/9 -> 60.111111 | AF35: =AF34/9 -> 66.666667 | AG35: =AG34/9 -> 56 | AH35: =AH34/9 -> 80.222222 | AI35: =+AI34/9 -> 56 | AJ35: =+AJ34/9 -> 60 | AK35: =AK34/9 -> 68 | AL35: =AL34/9 -> 78.111111 | AM35: =AM34/9 -> 86 | AN35: =AN34/9 -> 88.888889 | AO35: =+'Cell 10 603'!AI12 -> 75 | AP35: =+'Cell 10 603'!AJ12 -> 77.7 | AQ35: =+'Cell 10 603'!AK12 -> 66 | AR35: =+'Cell 10 603'!AL12 -> 68.75 | AS35: =+'Cell 10 603'!AM12 -> 63.6 | AT35: =+'Cell 10 603'!AN12 -> 56.666667 | AU35: =+'Cell 10 603'!AO12 -> 47.7 | AV35: =+'Cell 10 603'!AP12 -> 55 | ... BY35: =+'Cell 10 603'!BS12 -> 140
B36: Cell 9 | C36: < 1 Month | D36: 35 | E36: 31 | F36: =+E36-D36 -> -4 | G36: =G32 -> Output/Day | H36: 72 | I36: 126 | J36: 150 | L36: 107 | M36: 270 | N36: 180 | O36: 246 | P36: 342 | Q36: 402 | R36: 420 | AE36: 541 | AF36: 600 | AG36: 504 | AH36: 722 | AI36: 504 | AJ36: 540 | AK36: 612 | AL36: 703 | AM36: 774 | AN36: 800 | BJ36: =+'Cell 9 603'!F11 -> 0 | BK36: =+'Cell 9 603'!G11 -> 0 | BL36: =+'Cell 9 603'!H11 -> 0 | BM36: =+'Cell 9 603'!I11 -> 0 | BN36: =+'Cell 9 603'!J11 -> 108 | BO36: =+'Cell 9 603'!K11 -> 138 | BP36: =+'Cell 9 603'!L11 -> 132 | BQ36: =+'Cell 9 603'!M11 -> 0 | ... BY36: =+'Cell 9 603'!U11 -> 228
G37: Output/H | H37: =H36/9 -> 8 | I37: =I36/9 -> 14 | J37: =J36/9 -> 16.666667 | K37: =K36/9 -> 0 | L37: =+L36/9 -> 11.888889 | M37: =+M36/9 -> 30 | N37: =N36/9 -> 20 | O37: =O36/9 -> 27.333333 | P37: =P36/9 -> 38 | Q37: =Q36/9 -> 44.666667 | R37: =SUM(R36:R36)/8 -> 52.5 | S37: =S36/8 -> 0 | T37: =T36/8 -> 0 | U37: =U36/8 -> 0 | V37: =V36/8 -> 0 | W37: =W36/8 -> 0 | X37: =SUM(X36:X36)/8 -> 0 | Y37: =SUM(Y36:Y36)/8 -> 0 | Z37: =SUM(Z36:Z36)/8 -> 0 | AA37: =SUM(AA36:AA36)/8 -> 0 | AB37: =SUM(AB36:AB36)/8 -> 0 | AC37: =SUM(AC36:AC36)/8 -> 0 | AD37: =AD36/9 -> 0 | AE37: =AE36/9 -> 60.111111 | AF37: =AF36/9 -> 66.666667 | AG37: =AG36/9 -> 56 | AH37: =AH36/9 -> 80.222222 | AI37: =+AI36/9 -> 56 | AJ37: =+AJ36/9 -> 60 | AK37: =AK36/9 -> 68 | AL37: =AL36/9 -> 78.111111 | AM37: =AM36/9 -> 86 | AN37: =AN36/9 -> 88.888889 | BJ37: =+'Cell 9 603'!F12 -> 0 | BK37: =+'Cell 9 603'!G12 -> 0 | BL37: =+'Cell 9 603'!H12 -> 0 | BM37: =+'Cell 9 603'!I12 -> 0 | BN37: =+'Cell 9 603'!J12 -> 13.5 | BO37: =+'Cell 9 603'!K12 -> 17.25 | BP37: =+'Cell 9 603'!L12 -> 16.5 | BQ37: =+'Cell 9 603'!M12 -> 0 | ... BY37: =+'Cell 9 603'!U12 -> 25.333333
B38: Cell 11 | C38: 1 Month | D38: 35 | E38: 32 | F38: =+E38-D38 -> -3 | G38: =G34 -> Output/Day | H38: 72 | I38: 126 | J38: 150 | L38: 107 | M38: 270 | N38: 180 | O38: 246 | P38: 342 | Q38: 402 | R38: 420 | AE38: 541 | AF38: 600 | AG38: 504 | AH38: 722 | AI38: 504 | AJ38: 540 | AK38: 612 | AL38: 703 | AM38: 774 | AN38: 800 | AO38: =+'Cell 10 603'!AI15 -> 1060 | AP38: =+'Cell 10 603'!AJ15 -> 1050 | AQ38: =+'Cell 10 603'!AK15 -> 1025 | AR38: =+'Cell 10 603'!AL15 -> 1080 | AS38: =+'Cell 10 603'!AM15 -> 1050 | AT38: =+'Cell 10 603'!AN15 -> 840 | AU38: =+'Cell 10 603'!AO15 -> 870 | AV38: =+'Cell 10 603'!AP15 -> 830 | ... BE38: =+'Cell 10 603'!AY15 -> 674 | BJ38: =+'Cell 11 603'!Z11 -> 870 | BK38: =+'Cell 11 603'!AA11 -> 762 | BL38: =+'Cell 11 603'!AB11 -> 624 | BM38: =+'Cell 11 603'!AC11 -> 816 | BN38: =+'Cell 11 603'!AD11 -> 856 | BO38: =+'Cell 11 603'!AE11 -> 792 | BP38: =+'Cell 11 603'!AF11 -> 822 | BQ38: =+'Cell 11 603'!AG11 -> 744 | ... BY38: =+'Cell 11 603'!AO11 -> 1218
G39: Output/H | H39: =H38/9 -> 8 | I39: =I38/9 -> 14 | J39: =J38/9 -> 16.666667 | K39: =K38/9 -> 0 | L39: =+L38/9 -> 11.888889 | M39: =+M38/9 -> 30 | N39: =N38/9 -> 20 | O39: =O38/9 -> 27.333333 | P39: =P38/9 -> 38 | Q39: =Q38/9 -> 44.666667 | R39: =SUM(R38:R38)/8 -> 52.5 | S39: =S38/8 -> 0 | T39: =T38/8 -> 0 | U39: =U38/8 -> 0 | V39: =V38/8 -> 0 | W39: =W38/8 -> 0 | X39: =SUM(X38:X38)/8 -> 0 | Y39: =SUM(Y38:Y38)/8 -> 0 | Z39: =SUM(Z38:Z38)/8 -> 0 | AA39: =SUM(AA38:AA38)/8 -> 0 | AB39: =SUM(AB38:AB38)/8 -> 0 | AC39: =SUM(AC38:AC38)/8 -> 0 | AD39: =AD38/9 -> 0 | AE39: =AE38/9 -> 60.111111 | AF39: =AF38/9 -> 66.666667 | AG39: =AG38/9 -> 56 | AH39: =AH38/9 -> 80.222222 | AI39: =+AI38/9 -> 56 | AJ39: =+AJ38/9 -> 60 | AK39: =AK38/9 -> 68 | AL39: =AL38/9 -> 78.111111 | AM39: =AM38/9 -> 86 | AN39: =AN38/9 -> 88.888889 | AO39: =+'Cell 10 603'!AI16 -> 117.77778 | AP39: =+'Cell 10 603'!AJ16 -> 116.66667 | AQ39: =+'Cell 10 603'!AK16 -> 113.88889 | AR39: =+'Cell 10 603'!AL16 -> 120 | AS39: =+'Cell 10 603'!AM16 -> 105 | AT39: =+'Cell 10 603'!AN16 -> 84 | AU39: =+'Cell 10 603'!AO16 -> 96.666667 | AV39: =+'Cell 10 603'!AP16 -> 92.222222 | ... BE39: =+'Cell 10 603'!AY16 -> 96.285714 | BJ39: =+'Cell 11 603'!Z12 -> 72.5 | BK39: =+'Cell 11 603'!AA12 -> 63.5 | BL39: =+'Cell 11 603'!AB12 -> 52 | BM39: =+'Cell 11 603'!AC12 -> 68 | BN39: =+'Cell 11 603'!AD12 -> 71.333333 | BO39: =+'Cell 11 603'!AE12 -> 66 | BP39: =+'Cell 11 603'!AF12 -> 68.5 | BQ39: =+'Cell 11 603'!AG12 -> 74.4 | ... BY39: =+'Cell 11 603'!AO12 -> 101.5
B40: Cell D6 | C40: < 1 Month | D40: 35 | E40: 30 | F40: =+E40-D40 -> -5 | G40: =G34 -> Output/Day | H40: 72 | I40: 126 | J40: 150 | L40: 107 | M40: 270 | N40: 180 | O40: 246 | P40: 342 | Q40: 402 | R40: 420 | AE40: 541 | AF40: 600 | AG40: 504 | AH40: 722 | AI40: 504 | AJ40: 540 | AK40: 612 | AL40: 703 | AM40: 774 | AN40: 800 | AO40: =+'Cell 10 603'!AI34 -> 0 | AP40: =+'Cell 10 603'!AJ34 -> 0 | AQ40: =+'Cell 10 603'!AK34 -> 0 | AR40: =+'Cell 10 603'!AL34 -> 0 | AS40: =+'Cell 10 603'!AM34 -> 0 | AT40: =+'Cell 10 603'!AN34 -> 0 | AU40: =+'Cell 10 603'!AO34 -> 0 | AV40: =+'Cell 10 603'!AP34 -> 0 | ... BI40: =+'Cell 10 603'!BC34 -> 0 | BL40: =+'Cell D6'!R11 -> 102 | BM40: =+'Cell D6'!S11 -> 0 | BN40: =+'Cell D6'!T11 -> 192 | BO40: =+'Cell D6'!U11 -> 246 | BP40: =+'Cell D6'!V11 -> 162 | BQ40: =+'Cell D6'!W11 -> 102 | BR40: =+'Cell D6'!X11 -> 232 | BS40: =+'Cell D6'!Y11 -> 150 | ... BY40: =+'Cell D6'!AE11 -> 217
G41: Output/H | H41: =H40/9 -> 8 | I41: =I40/9 -> 14 | J41: =J40/9 -> 16.666667 | K41: =K40/9 -> 0 | L41: =+L40/9 -> 11.888889 | M41: =+M40/9 -> 30 | N41: =N40/9 -> 20 | O41: =O40/9 -> 27.333333 | P41: =P40/9 -> 38 | Q41: =Q40/9 -> 44.666667 | R41: =SUM(R40:R40)/8 -> 52.5 | S41: =S40/8 -> 0 | T41: =T40/8 -> 0 | U41: =U40/8 -> 0 | V41: =V40/8 -> 0 | W41: =W40/8 -> 0 | X41: =SUM(X40:X40)/8 -> 0 | Y41: =SUM(Y40:Y40)/8 -> 0 | Z41: =SUM(Z40:Z40)/8 -> 0 | AA41: =SUM(AA40:AA40)/8 -> 0 | AB41: =SUM(AB40:AB40)/8 -> 0 | AC41: =SUM(AC40:AC40)/8 -> 0 | AD41: =AD40/9 -> 0 | AE41: =AE40/9 -> 60.111111 | AF41: =AF40/9 -> 66.666667 | AG41: =AG40/9 -> 56 | AH41: =AH40/9 -> 80.222222 | AI41: =+AI40/9 -> 56 | AJ41: =+AJ40/9 -> 60 | AK41: =AK40/9 -> 68 | AL41: =AL40/9 -> 78.111111 | AM41: =AM40/9 -> 86 | AN41: =AN40/9 -> 88.888889 | AO41: =+'Cell 10 603'!AI35 -> 0 | AP41: =+'Cell 10 603'!AJ35 -> 0 | AQ41: =+'Cell 10 603'!AK35 -> 0 | AR41: =+'Cell 10 603'!AL35 -> 0 | AS41: =+'Cell 10 603'!AM35 -> 0 | AT41: =+'Cell 10 603'!AN35 -> 0 | AU41: =+'Cell 10 603'!AO35 -> 0 | AV41: =+'Cell 10 603'!AP35 -> 0 | ... BI41: =+'Cell 10 603'!BC35 -> 0 | BL41: =+'Cell D6'!R12 -> 11.333333 | BM41: =+'Cell D6'!S12 -> 0 | BN41: =+'Cell D6'!T12 -> 21.333333 | BO41: =+'Cell D6'!U12 -> 27.333333 | BP41: =+'Cell D6'!V12 -> 18 | BQ41: =+'Cell D6'!W12 -> 11.333333 | BR41: =+'Cell D6'!X12 -> 25.777778 | BS41: =+'Cell D6'!Y12 -> 16.666667 | ... BY41: =+'Cell D6'!AE12 -> 18.083333
B42: TARGET RUMP UP LEAN | H42: 12 | I42: 12 | J42: 12 | K42: 12 | L42: 12 | M42: 24 | N42: 24 | O42: 24 | P42: 24 | Q42: 24 | R42: 48 | S42: 48 | T42: 48 | U42: 48 | V42: 48 | W42: 60 | X42: 60 | Y42: 60 | Z42: 60 | AA42: 60 | AB42: 72 | AC42: 72 | AD42: 72 | AE42: 72 | AF42: 72 | AG42: 96 | AH42: 96 | AI42: 96 | AJ42: 96 | AK42: 96 | AL42: 108 | AM42: 108 | AN42: 108 | AO42: 120 | AP42: 120 | AQ42: 120 | AR42: 120 | AS42: 120 | AT42: 120 | AU42: 120 | AV42: 120 | AW42: 120 | AX42: 120 | AY42: 120 | AZ42: 120 | BA42: 120 | BB42: 120 | BC42: 120 | BD42: 120 | BE42: 120 | BF42: 120 | BG42: 120 | BH42: 120 | BI42: 120 | BJ42: 120 | BK42: 120 | BL42: 120 | BM42: 120 | BN42: 120 | BO42: 120 | BP42: 120 | BQ42: 120 | BR42: 120 | BS42: 120 | BT42: 120 | BU42: 120 | BV42: 120 | BW42: 120 | BX42: 120 | BY42: 120 | BZ42: 120 | CA42: 120 | CB42: 120 | CC42: 120 | CD42: 120 | CE42: 120 | CF42: 120 | CG42: 120 | CH42: 120 | CI42: 120 | CJ42: 120 | CK42: 120 | CL42: 108 | CM42: 108 | CN42: 120 | CO42: 120 | CP42: 120 | CQ42: 120 | CR42: 120 | CS42: 120 | CT42: 120 | CU42: 120 | CV42: 120 | CW42: 120 | CX42: 120 | CY42: 120 | CZ42: 120 | DA42: 120 | DB42: 120 | DC42: 120 | DD42: 120 | DE42: 120 | DF42: 120 | DG42: 120 | DH42: 120 | DI42: 120 | DJ42: 120 | DK42: 120 | DL42: 120 | DM42: 120 | DN42: 120 | DO42: 120 | DP42: 120 | DQ42: 120 | DR42: 120 | DS42: 120 | DT42: 120 | DU42: 120 | DV42: 120 | DW42: 120 | DX42: 120 | DY42: 120 | DZ42: 120 | EA42: 120 | EB42: 120 | EC42: 120
B45: SEWING
B48: Cell | C48: Working Period | D48: STD MP | E48: ACT MP | F48: Gap | G48: Output | H48: Hari ke- | AO48: Day
H49: 1 | I49: 2 | J49: 3 | K49: 4 | L49: 5 | M49: =1+L49 -> 6 | N49: =1+M49 -> 7 | O49: =1+N49 -> 8 | P49: =1+O49 -> 9 | Q49: =1+P49 -> 10 | R49: =1+Q49 -> 11 | S49: =1+R49 -> 12 | T49: =1+S49 -> 13 | ... DE49: =1+DD49 -> 102 | DF49: =1+BF49 -> 52 | DG49: =1+DF49 -> 53 | DH49: =1+DG49 -> 54 | DI49: =1+DH49 -> 55 | DJ49: =1+DI49 -> 56 | DK49: =1+DJ49 -> 57 | DL49: =1+DK49 -> 58 | DM49: =1+DL49 -> 59 | DN49: =1+DM49 -> 60 | ... EC49: =1+EB49 -> 75
H50: 46013 | I50: 46014 | J50: 46015 | K50: 46017 | L50: 46020 | M50: 46021 | N50: 46022 | O50: 46024 | P50: 46027 | Q50: 46028 | R50: 46029 | S50: 46030 | T50: 46031 | U50: 46034 | V50: 46035 | W50: 46036 | X50: 46037 | Y50: 46039 | Z50: 46041 | AA50: 46042 | AB50: 46043 | AC50: 46044 | AD50: 46045 | AE50: 46048 | AF50: 46049 | AG50: 46050 | AH50: 46051 | AI50: 46052 | AJ50: 46055 | AK50: 46056 | AL50: 46057 | AM50: 46058 | AN50: 46059 | AO50: 46083 | AP50: 46084 | AQ50: 46085 | AR50: 46086 | AS50: 46087 | AT50: 46090 | AU50: 46091 | AV50: 46092 | AW50: 46093 | AX50: 46094 | AY50: 46097 | AZ50: 46098 | BA50: 46099 | BB50: 46106 | BC50: 46107 | BD50: 46108 | BE50: 46109 | BF50: 46111 | BG50: 45747 | BH50: 46113 | BI50: 46114 | BJ50: 46115 | BK50: 46116 | BL50: 46118 | BM50: 46119 | BN50: 46120 | BO50: 46121 | BP50: 46122 | BQ50: 46123 | BR50: 46125 | BS50: 46126 | BT50: 46127 | BU50: 46128 | BV50: 46129 | BW50: 46130 | BX50: 46132 | BY50: 46133 | BZ50: 46134 | CA50: 46135 | CB50: 46136 | CC50: 46137 | CD50: 46138 | CE50: 46139 | CF50: 46140 | CG50: 46141 | CH50: 46142 | CI50: 46143 | CJ50: 46144 | CK50: 46145 | CL50: 45778 | CM50: 45779 | CN50: 45780 | CO50: 45781 | CP50: 45782 | CQ50: 45783 | CR50: 45784 | CS50: 45785 | CT50: 45786 | CU50: 45787 | CV50: 45788 | CW50: 45789 | CX50: 45790 | CY50: 45791 | CZ50: 45792 | DA50: 45793 | DB50: 45794 | DC50: 45795 | DD50: 45796 | DE50: 45797 | DF50: 45798 | DG50: 45799 | DH50: 45800 | DI50: 45801 | DJ50: 45802 | DK50: 45803 | DL50: 45804 | DM50: 45805 | DN50: 45806 | DO50: 45807 | DP50: 45808 | DQ50: 45809 | DR50: 45810 | DS50: 45811 | DT50: 45812 | DU50: 45813 | DV50: 45814 | DW50: 45815 | DX50: 45816 | DY50: 45817 | DZ50: 45818 | EA50: 45819 | EB50: 45820 | EC50: 45821
B51: Cell 4 | C51: 3 Month | D51: 29 | E51: 29 | F51: =+E51-D51 -> 0 | G51: Output/Day | H51: 468 | I51: 522 | J51: 300 | L51: 276 | M51: 540 | N51: 444 | O51: 462 | P51: 600 | Q51: 582 | R51: 429 | AE51: 600 | AF51: 600 | AG51: 612 | AH51: 672 | AI51: 348 | AJ51: 468 | AK51: 552 | AL51: 316 | AM51: 503 | AN51: 690 | AO51: =+'Cell 4 603'!BB13 -> 636 | AP51: =+'Cell 4 603'!BC13 -> 702 | AQ51: =+'Cell 4 603'!BD13 -> 630 | AR51: =+'Cell 4 603'!BE13 -> 546 | AS51: =+'Cell 4 603'!BF13 -> 540 | AT51: =+'Cell 4 603'!BG13 -> 510 | AU51: =+'Cell 4 603'!BH13 -> 600 | AV51: =+'Cell 4 603'!BI13 -> 600 | ... BY51: =+'Cell 4 603'!CL13 -> 980
G52: Output/H | H52: =H51/8 -> 58.5 | I52: =I51/8 -> 65.25 | J52: =J51/10 -> 30 | K52: =K51/8 -> 0 | L52: =+L51/8 -> 34.5 | M52: =+M51/8 -> 67.5 | N52: =N51/10 -> 44.4 | O52: =O51/10 -> 46.2 | P52: =P51/10 -> 60 | Q52: =Q51/10 -> 58.2 | R52: =SUM(R51:R51)/8 -> 53.625 | S52: =S51/8 -> 0 | T52: =T51/8 -> 0 | U52: =U51/8 -> 0 | V52: =V51/8 -> 0 | W52: =W51/8 -> 0 | X52: =SUM(X51:X51)/8 -> 0 | Y52: =SUM(Y51:Y51)/8 -> 0 | Z52: =SUM(Z51:Z51)/8 -> 0 | AA52: =SUM(AA51:AA51)/8 -> 0 | AB52: =SUM(AB51:AB51)/8 -> 0 | AC52: =SUM(AC51:AC51)/8 -> 0 | AD52: =AD51/8 -> 0 | AE52: =AE51/8 -> 75 | AF52: =AF51/8 -> 75 | AG52: =AG51/10 -> 61.2 | AH52: =AH51/8 -> 84 | AI52: =+AI51/8 -> 43.5 | AJ52: =+AJ51/8 -> 58.5 | AK52: =AK51/9 -> 61.333333 | AL52: =AL51/8 -> 39.5 | AM52: =AM51/8 -> 62.875 | AN52: =SUM(AN51:AN51)/8 -> 86.25 | AO52: =+'Cell 4 603'!BB14 -> 63.6 | AP52: =+'Cell 4 603'!BC14 -> 70.2 | AQ52: =+'Cell 4 603'!BD14 -> 63 | AR52: =+'Cell 4 603'!BE14 -> 54.6 | AS52: =+'Cell 4 603'!BF14 -> 54 | AT52: =+'Cell 4 603'!BG14 -> 51 | AU52: =+'Cell 4 603'!BH14 -> 60 | AV52: =+'Cell 4 603'!BI14 -> 60 | ... BY52: =+'Cell 4 603'!CL14 -> 81.666667
...

Sheet Computer Stitching PerHour
A2: , | B2: `
B4: Tanggal | C4: Cell | D4: PIC | E4: Process | F4: No. COS | H4: Type Mesin | I4: CT | J4: STD MP | K4: ACT MP | L4: Target | M4: Jam ke 1 | N4: Jam ke 2 | O4: Jam ke 3 | P4: Jam ke 4 | Q4: Jam ke 5 | R4: Jam ke 6 | S4: Jam ke 7 | T4: Jam ke 8 | U4: Total
B5: 46129 | C5: 3 | D5: PRASETYO | E5: Middle Eyestay | H5: CS 3020 | J5: 2 | K5: 2 | L5: 120 | U5: =SUM(M5:T5) -> 0
E6: Total | L6: =SUM(L5) -> 120 | M6: =SUM(M5) -> 0 | N6: =SUM(N5) -> 0 | O6: =SUM(O5) -> 0 | P6: =SUM(P5) -> 0 | Q6: =SUM(Q5) -> 0 | R6: =SUM(R5) -> 0 | S6: =SUM(S5) -> 0 | ... U6: =SUM(U5) -> 0
E7: Vamp Olay + Tip Accent | H7: CS 6040 | J7: 6 | K7: 4 | L7: 40 | U7: =SUM(M7:T7) -> 0
E8: Vamp Olay + Tip Accent | H8: CS 6040 | L8: 40 | U8: =SUM(M8:T8) -> 0
E9: Vamp Olay + Tip Accent | H9: CS 6040 | L9: 40 | U9: =SUM(M9:T9) -> 0
E10: Total | L10: =SUM(L7:L9) -> 120 | M10: =SUM(M7:M9) -> 0 | N10: =SUM(N7:N9) -> 0 | O10: =SUM(O7:O9) -> 0 | P10: =SUM(P7:P9) -> 0 | Q10: =SUM(Q7:Q9) -> 0 | R10: =SUM(R7:R9) -> 0 | S10: =SUM(S7:S9) -> 0 | ... U10: =SUM(U7:U9) -> 0
E11: Foxing Ulay + Collar L&M | H11: CS 6040 | J11: 6 | K11: 5 | L11: 40 | U11: =SUM(M11:T11) -> 0
E12: Foxing Ulay + Collar L&M | H12: CS 6040 | L12: 40 | U12: =SUM(M12:T12) -> 0
E13: Foxing Ulay + Collar L&M | H13: CS 6040 | L13: 40 | U13: =SUM(M13:T13) -> 0
E14: Total | L14: =SUM(L11:L13) -> 120 | M14: =SUM(M11:M13) -> 0 | N14: =SUM(N11:N13) -> 0 | O14: =SUM(O11:O13) -> 0 | P14: =SUM(P11:P13) -> 0 | Q14: =SUM(Q11:Q13) -> 0 | R14: =SUM(R11:R13) -> 0 | S14: =SUM(S11:S13) -> 0 | ... U14: =SUM(U11:U13) -> 0
E15: Mudguard LM + Tip Ulay + Top Eyestay | H15: CS 6040 | J15: 8 | K15: 8 | L15: 30 | U15: =SUM(M15:T15) -> 0
E16: Mudguard LM + Tip Ulay + Top Eyestay | H16: CS 6040 | L16: 30 | U16: =SUM(M16:T16) -> 0
E17: Mudguard LM + Tip Ulay + Top Eyestay | H17: CS 6040 | L17: 30 | U17: =SUM(M17:T17) -> 0
E18: Mudguard LM + Tip Ulay + Top Eyestay | H18: CS 6040 | L18: 30 | U18: =SUM(M18:T18) -> 0
E19: Total | L19: =SUM(L15:L18) -> 120 | M19: =SUM(M15:M18) -> 0 | N19: =SUM(N15:N18) -> 0 | O19: =SUM(O15:O18) -> 0 | P19: =SUM(P15:P18) -> 0 | Q19: =SUM(Q15:Q18) -> 0 | R19: =SUM(R15:R18) -> 0 | S19: =SUM(S15:S18) -> 0 | ... U19: =SUM(U15:U18) -> 0
E20: Project Support Mudguard Manual | J20: 8 | K20: 0
E23: ACTION PLAN
E24: CELL 3 | F24: 07:00-08:00
F25: 08:00-09:00
F26: 09:00-10:00
F27: 10:00-11:00
F28: 11:00-12:00
F29: 13:00-14:00
F30: 14:00-15:00
E31: PIC : PRASETYO | F31: 15:00-16:00
B35: Tanggal | C35: Cell | D35: PIC | E35: Process | F35: Operator | G35: Work Period | H35: Type Mesin | I35: CT | J35: STD MP | K35: ACT MP | L35: Target | M35: Jam ke 1 | N35: Jam ke 2 | O35: Jam ke 3 | P35: Jam ke 4 | Q35: Jam ke 5 | R35: Jam ke 6 | S35: Jam ke 7 | T35: Jam ke 8 | U35: Total
B36: 46129 | C36: 4 | D36: PRASETYO | E36: Middle Eyestay | F36: 1 (Sofi) | G36: 4 Month | H36: CS 1510 | I36: 79.1 | J36: 2 | K36: 2 | L36: 60 | M36: 42 | N36: 42 | O36: 30 | P36: 48 | Q36: 24 | R36: 6 | S36: 30 | T36: 12 | U36: =SUM(M36:T36) -> 234
E37: Middle Eyestay | F37: 2 (Nina) | G37: 4 Month | H37: CS 1510 | L37: 60 | M37: 24 | N37: 24 | O37: 30 | P37: 30 | Q37: 18 | R37: 6 | S37: 24 | T37: 12 | U37: =SUM(M37:T37) -> 168
E38: Total | L38: =SUM(L36:L37) -> 120 | M38: =SUM(M36:M37) -> 66 | N38: =SUM(N36:N37) -> 66 | O38: =SUM(O36:O37) -> 60 | P38: =SUM(P36:P37) -> 78 | Q38: =SUM(Q36:Q37) -> 42 | R38: =SUM(R36:R37) -> 12 | S38: =SUM(S36:S37) -> 54 | ... U38: =SUM(U36:U37) -> 402
E39: Vamp Olay + Tip Accent | F39: 1 (Laura) | G39: 4 Month | H39: CS 6040 | I39: 140.3 | J39: 6 | K39: 5 | L39: 40 | M39: 36 | N39: 18 | O39: 18 | P39: 24 | Q39: 24 | R39: 24 | S39: 25 | T39: 13 | U39: =SUM(M39:T39) -> 182
E40: Vamp Olay + Tip Accent | F40: 2 (Titik) | G40: 4 Month | H40: CS 6040 | L40: 40 | M40: 36 | N40: 24 | O40: 30 | P40: 36 | Q40: 30 | R40: 12 | S40: 24 | T40: 6 | U40: =SUM(M40:T40) -> 198
E41: Vamp Olay + Tip Accent | F41: 3 (Anis) | G41: 4 Month | H41: CS 6040 | L41: 40 | M41: 6 | N41: 6 | O41: - | P41: 6 | Q41: 6 | R41: 12 | S41: 6 | T41: 6 | U41: =SUM(M41:T41) -> 48
E42: Total | L42: =SUM(L39:L41) -> 120 | M42: =SUM(M39:M41) -> 78 | N42: =SUM(N39:N41) -> 48 | O42: =SUM(O39:O41) -> 48 | P42: =SUM(P39:P41) -> 66 | Q42: =SUM(Q39:Q41) -> 60 | R42: =SUM(R39:R41) -> 48 | S42: =SUM(S39:S41) -> 55 | ... U42: =SUM(U39:U41) -> 428
E43: Foxing Ulay + Collar L&M | F43: 1 (Ichda) | G43: 16 Month | H43: CS 6040 | I43: 142.1 | J43: 6 | K43: 5 | L43: 40 | M43: 12 | N43: 6 | O43: 30 | P43: 30 | Q43: 30 | R43: 30 | S43: 18 | T43: 6 | U43: =SUM(M43:T43) -> 162
E44: Foxing Ulay + Collar L&M | F44: 2 (Sunarni) | G44: 4 Month | H44: CS 6040 | L44: 40 | M44: 30 | N44: 30 | O44: 24 | P44: 18 | Q44: 30 | R44: 30 | S44: 30 | T44: 25 | U44: =SUM(M44:T44) -> 217
E45: Foxing Ulay + Collar L&M | F45: 3 (Usni) | G45: 4 Month | H45: CS 6040 | L45: 40 | M45: 30 | N45: 30 | O45: 30 | P45: 18 | Q45: 18 | R45: 18 | S45: 12 | T45: 18 | U45: =SUM(M45:T45) -> 174
E46: Total | L46: =SUM(L43:L45) -> 120 | M46: =SUM(M43:M45) -> 72 | N46: =SUM(N43:N45) -> 66 | O46: =SUM(O43:O45) -> 84 | P46: =SUM(P43:P45) -> 66 | Q46: =SUM(Q43:Q45) -> 78 | R46: =SUM(R43:R45) -> 78 | S46: =SUM(S43:S45) -> 60 | ... U46: =SUM(U43:U45) -> 553
E47: Mudguard LM + Tip Ulay + Top Eyestay | F47: 1 (Nia) | G47: 16 Month | H47: CS 6040 | I47: 178.2 | J47: 8 | K47: 8 | L47: 30 | M47: 18 | N47: 18 | O47: 18 | P47: 12 | Q47: 12 | R47: 22 | S47: 12 | T47: 13 | U47: =SUM(M47:T47) -> 125
...

Sheet Cell 3 603
B4: Model 603 | D4: CELL 3 | Q4: Target: 120 Prs | AK4: Target : 120 Prs/H | BX4: Cell 4
B6: Description | C6: Output | D6: Day
D7: 1 | E7: 2 | F7: 3 | G7: 4 | H7: 5 | I7: =1+H7 -> 6 | J7: =1+I7 -> 7 | K7: =1+J7 -> 8 | L7: =1+K7 -> 9 | M7: =1+L7 -> 10 | N7: =1+M7 -> 11 | O7: =1+N7 -> 12 | P7: =1+O7 -> 13 | ... BY7: =1+BX7 -> 74
D8: 46115 | E8: 46116 | F8: 46118 | G8: 46119 | H8: 46120 | I8: 46121 | J8: 46122 | K8: 46123 | L8: 46125 | M8: 46126 | N8: 46127 | O8: 46128 | P8: 46129 | Q8: 46130 | R8: 46132 | S8: 46133 | T8: 46134 | U8: 46135 | V8: 46136 | W8: 46137 | X8: 46138 | Y8: 46139 | Z8: 46140 | AA8: 46141 | AB8: 46142 | AC8: 46143 | AD8: 46144 | AE8: 46145 | AF8: 46146 | AG8: 46147 | AH8: 46148 | AI8: 46149 | AJ8: 46150 | AK8: 46151 | AL8: 46152 | AM8: 46153 | AN8: 46154 | AO8: 46155 | AP8: 46156 | AQ8: 46157 | AR8: 46158 | AS8: 46159 | AT8: 46160 | AU8: 46161 | AV8: 46162 | AW8: 46163 | AX8: 46164 | AY8: 46165 | AZ8: 46166 | BA8: 46167 | BB8: 46168 | BC8: 46169 | BD8: 46170 | BE8: 46171 | BF8: 46172 | BG8: 46173 | BH8: 46174 | BI8: 46175 | BJ8: 46176 | BK8: 46177 | BL8: 46178 | BM8: 46179 | BN8: 46180 | BO8: 46181 | BP8: 46182 | BQ8: 46183 | BR8: 46184 | BS8: 46185 | BT8: 46186 | BU8: 46187 | BV8: 46188 | BW8: 46189 | BX8: 46190 | BY8: 46191
B9: Cutting+Prep | C9: Output/Day | D9: 642 | E9: 0 | F9: 282 | G9: 0 | H9: 546 | I9: 0 | J9: 120 | K9: 0 | L9: 1410 | M9: 810 | N9: 858 | O9: 648 | P9: 450 | Q9: 180 | R9: 300 | S9: 500
C10: Output/H | D10: =D9/8 -> 80.25 | E10: =E9/8 -> 0 | F10: =F9/10 -> 28.2 | G10: =G9/8 -> 0 | H10: =+H9/8 -> 68.25 | I10: =+I9/8 -> 0 | J10: =J9/10 -> 12 | K10: =K9/10 -> 0 | L10: =L9/8 -> 176.25 | M10: =M9/8 -> 101.25 | N10: =+N9/8 -> 107.25 | O10: =O9/8 -> 81 | P10: =P9/8 -> 56.25 | Q10: =Q9/8 -> 22.5 | R10: =R9/8 -> 37.5 | S10: =S9/8 -> 62.5 | T10: =SUM(T9:T9)/8 -> 0 | U10: =SUM(U9:U9)/8 -> 0 | V10: =SUM(V9:V9)/8 -> 0 | W10: =SUM(W9:W9)/8 -> 0 | X10: =SUM(X9:X9)/8 -> 0 | Y10: =SUM(Y9:Y9)/8 -> 0 | Z10: =Z9/8 -> 0 | AA10: =AA9/8 -> 0 | AB10: =AB9/8 -> 0 | AC10: =AC9/10 -> 0 | AD10: =AD9/8 -> 0 | AE10: =+AE9/8 -> 0 | AF10: =+AF9/8 -> 0 | AG10: =AG9/9 -> 0 | AH10: =AH9/8 -> 0 | AI10: =AI9/8 -> 0 | AJ10: =SUM(AJ9:AJ9)/8 -> 0 | AK10: =AK9/8 -> 0 | AL10: =AL9/8 -> 0 | AM10: =AM9/8 -> 0 | AN10: =AN9/8 -> 0 | AO10: =AO9/8 -> 0 | AP10: =AP9/9 -> 0 | AQ10: =AQ9/5 -> 0 | AR10: =AR9/9 -> 0 | AS10: =AS9/10 -> 0 | AT10: =AT9/8 -> 0 | AU10: =AU9/7 -> 0 | AV10: =AV9/9 -> 0 | AW10: =AW9/9 -> 0 | AX10: =AX9/9 -> 0 | AY10: =AY9/9 -> 0 | AZ10: =AZ9/8 -> 0 | BA10: =BA9/5 -> 0 | BB10: =BB9/8 -> 0 | BC10: =BC9/8 -> 0 | BD10: =BD9/8 -> 0 | BE10: =BE9/8 -> 0 | BF10: =BF9/8 -> 0 | BG10: =BG9/8 -> 0 | BH10: =BH9/8 -> 0 | BI10: =BI9/8 -> 0 | ... BM10: =BM9/8 -> 0 | BN10: =BN9/9 -> 0 | BO10: =BO9/9 -> 0 | BP10: =BP9/9 -> 0 | BQ10: =BQ9/9 -> 0 | BR10: =BR9/7 -> 0 | BS10: =BS9/10 -> 0 | BT10: =BT9/10 -> 0 | BU10: =BU9/9 -> 0 | BV10: =BV9/9 -> 0 | BW10: =BW9/9 -> 0 | BX10: =BX9/9 -> 0 | BY10: =BY9/9 -> 0
B11: Comshare | C11: =C9 -> Output/Day | N11: 84 | O11: 96 | P11: 162 | R11: 384 | S11: 336
C12: Output/H | D12: =D11/9 -> 0 | E12: =E11/9 -> 0 | F12: =F11/10 -> 0 | G12: =G11/9 -> 0 | H12: =+H11/9 -> 0 | I12: =+I11/9 -> 0 | J12: =J11/10 -> 0 | K12: =K11/10 -> 0 | L12: =L11/10 -> 0 | M12: =M11/10 -> 0 | N12: =+N11/8 -> 10.5 | O12: =O11/8 -> 12 | P12: =P11/8 -> 20.25 | Q12: =Q11/8 -> 0 | R12: =R11/8 -> 48 | S12: =S11/8 -> 42 | T12: =SUM(T11:T11)/8 -> 0 | U12: =SUM(U11:U11)/8 -> 0 | V12: =SUM(V11:V11)/8 -> 0 | W12: =SUM(W11:W11)/8 -> 0 | X12: =SUM(X11:X11)/8 -> 0 | Y12: =SUM(Y11:Y11)/8 -> 0 | Z12: =Z11/9 -> 0 | AA12: =AA11/9 -> 0 | AB12: =AB11/9 -> 0 | AC12: =AC11/10 -> 0 | AD12: =AD11/9 -> 0 | AE12: =+AE11/9 -> 0 | AF12: =+AF11/9 -> 0 | AG12: =AG11/9 -> 0 | AH12: =AH11/9 -> 0 | AI12: =AI11/9 -> 0 | AJ12: =AJ11/9 -> 0 | AK12: =AK11/9 -> 0 | AL12: =AL11/10 -> 0 | AM12: =AM11/9 -> 0 | AN12: =AN11/10 -> 0 | AO12: =AO11/9 -> 0 | AP12: =AP11/9 -> 0 | AQ12: =AQ11/7 -> 0 | AR12: =AR11/10 -> 0 | AS12: =AS11/10 -> 0 | AT12: =AT11/9 -> 0 | AU12: =AU11/7 -> 0 | AV12: =AV11/10 -> 0 | AW12: =AW11/10 -> 0 | AX12: =AX11/10 -> 0 | AY12: =AY11/10 -> 0 | AZ12: =AZ11/10 -> 0 | BA12: =BA11/7 -> 0 | BB12: =BB11/10 -> 0 | BC12: =BC11/10 -> 0 | BD12: =BD11/10 -> 0 | BE12: =BE11/10 -> 0 | BF12: =BF11/10 -> 0 | BG12: =BG11/10 -> 0 | BH12: =BH11/10 -> 0 | BI12: =BI11/10 -> 0 | BJ12: =+BJ11/10 -> 0 | BK12: =+BK11/10 -> 0 | BL12: =+BL11/10 -> 0 | BM12: =+BM11/10 -> 0 | BN12: =+BN11/10 -> 0 | BO12: =+BO11/10 -> 0 | BP12: =+BP11/10 -> 0 | BQ12: =+BQ11/10 -> 0 | BR12: =+BR11/10 -> 0 | BS12: =+BS11/11 -> 0 | BT12: =+BT11/11 -> 0 | BU12: =+BU11/10 -> 0 | BV12: =+BV11/10 -> 0 | BW12: =+BW11/10 -> 0 | BX12: =+BX11/10 -> 0 | BY12: =+BY11/10 -> 0
B13: Sewing | C13: =C9 -> Output/Day | N13: 168 | O13: 222 | P13: 300 | R13: 348 | S13: 420
C14: Output/H | D14: =D13/9 -> 0 | E14: =E13/9 -> 0 | F14: =F13/9 -> 0 | G14: =G13/9 -> 0 | H14: =+H13/9 -> 0 | I14: =+I13/9 -> 0 | J14: =J13/9 -> 0 | K14: =K13/9 -> 0 | L14: =L13/9 -> 0 | M14: =M13/9 -> 0 | N14: =+N13/8 -> 21 | O14: =O13/8 -> 27.75 | P14: =P13/8 -> 37.5 | Q14: =Q13/8 -> 0 | R14: =R13/8 -> 43.5 | S14: =S13/8 -> 52.5 | T14: =SUM(T13:T13)/8 -> 0 | U14: =SUM(U13:U13)/8 -> 0 | V14: =SUM(V13:V13)/8 -> 0 | W14: =SUM(W13:W13)/8 -> 0 | X14: =SUM(X13:X13)/8 -> 0 | Y14: =SUM(Y13:Y13)/8 -> 0 | Z14: =Z13/9 -> 0 | AA14: =AA13/9 -> 0 | AB14: =AB13/9 -> 0 | AC14: =AC13/9 -> 0 | AD14: =AD13/9 -> 0 | AE14: =+AE13/9 -> 0 | AF14: =+AF13/9 -> 0 | AG14: =AG13/9 -> 0 | AH14: =AH13/9 -> 0 | AI14: =AI13/9 -> 0 | AJ14: =AJ13/9 -> 0 | AK14: =AK13/9 -> 0 | AL14: =AL13/10 -> 0 | AM14: =AM13/9 -> 0 | AN14: =AN13/10 -> 0 | AO14: =AO13/9 -> 0 | AP14: =AP13/9 -> 0 | AQ14: =AQ13/7 -> 0 | AR14: =AR13/10 -> 0 | AS14: =AS13/10 -> 0 | AT14: =AT13/9 -> 0 | AU14: =AU13/7 -> 0 | AV14: =AV13/10 -> 0 | AW14: =AW13/10 -> 0 | AX14: =AX13/10 -> 0 | AY14: =AY13/10 -> 0 | AZ14: =AZ13/10 -> 0 | BA14: =BA13/7 -> 0 | BB14: =BB13/10 -> 0 | BC14: =BC13/10 -> 0 | BD14: =BD13/10 -> 0 | BE14: =BE13/10 -> 0 | BF14: =BF13/10 -> 0 | BG14: =BG13/10 -> 0 | BH14: =BH13/10 -> 0 | BI14: =BI13/10 -> 0 | ... BR14: =BR13/10 -> 0 | BS14: =BS13/11 -> 0 | BT14: =BT13/11 -> 0 | BU14: =BU13/10 -> 0 | BV14: =BV13/10 -> 0 | BW14: =BW13/10 -> 0 | BX14: =BX13/10 -> 0 | BY14: =BY13/10 -> 0
B15: Assembly | C15: =C9 -> Output/Day
C16: Output/H | D16: =D15/8 -> 0 | E16: =E15/8 -> 0 | F16: =F15/8 -> 0 | G16: =G15/8 -> 0 | H16: =H15/8 -> 0 | I16: =+I15/8 -> 0 | J16: =J15/8 -> 0 | K16: =K15/8 -> 0 | L16: =L15/8 -> 0 | M16: =M15/8 -> 0 | N16: =SUM(N15:N15)/8 -> 0 | O16: =SUM(O15:O15)/8 -> 0 | P16: =SUM(P15:P15)/8 -> 0 | Q16: =SUM(Q15:Q15)/8 -> 0 | R16: =SUM(R15:R15)/8 -> 0 | S16: =SUM(S15:S15)/8 -> 0 | T16: =SUM(T15:T15)/8 -> 0 | U16: =SUM(U15:U15)/8 -> 0 | ... Y16: =SUM(Y15:Y15)/8 -> 0 | Z16: =Z15/8 -> 0 | AA16: =AA15/8 -> 0 | AB16: =AB15/8 -> 0 | AC16: =AC15/8 -> 0 | AD16: =AD15/8 -> 0 | AE16: =AE15/8 -> 0 | AF16: =+AF15/8 -> 0 | AG16: =AG15/8 -> 0 | AH16: =AH15/8 -> 0 | AI16: =AI15/8 -> 0 | AJ16: =AJ15/8 -> 0 | AK16: =AK15/9 -> 0 | AL16: =AL15/9 -> 0 | AM16: =AM15/9 -> 0 | AN16: =AN15/9 -> 0 | AO16: =AO15/9 -> 0 | AP16: =AP15/9 -> 0 | AQ16: =AQ15/5 -> 0 | AR16: =AR15/9 -> 0 | AS16: =AS15/9 -> 0 | AT16: =AT15/9 -> 0 | AU16: =AU15/5 -> 0 | AV16: =AV15/9 -> 0 | AW16: =AW15/9 -> 0 | AX16: =AX15/9 -> 0 | AY16: =AY15/9 -> 0 | AZ16: =AZ15/9 -> 0 | BA16: =BA15/7 -> 0 | BB16: =BB15/9 -> 0 | BC16: =BC15/10 -> 0 | BD16: =BD15/9 -> 0 | BE16: =BE15/9 -> 0 | BF16: =BF15/9 -> 0 | BG16: =BG15/9 -> 0 | BH16: =BH15/9 -> 0 | BI16: =BI15/9 -> 0 | BJ16: =BJ15/9 -> 0 | BK16: =BK15/9 -> 0 | BL16: =BL15/8 -> 0 | BM16: =BM15/9 -> 0 | BN16: =BN15/9 -> 0 | BO16: =BO15/9 -> 0 | BP16: =BP15/9 -> 0 | BQ16: =BQ15/9 -> 0 | BR16: =BR15/7 -> 0 | BS16: =BS15/12 -> 0 | BT16: =BT15/11 -> 0 | BU16: =BU15/9 -> 0 | BV16: =BV15/9 -> 0 | BW16: =BW15/9 -> 0 | BX16: =BX15/9 -> 0 | BY16: =BY15/9 -> 0
B17: TARGET RUMP UP LEAN | D17: 12 | E17: 12 | F17: 12 | G17: 12 | H17: 12 | I17: 24 | J17: 24 | K17: 24 | L17: 24 | M17: 24 | N17: 48 | O17: 48 | P17: 48 | Q17: 48 | R17: 48 | S17: 60 | T17: 60 | U17: 60 | V17: 60 | W17: 60 | X17: 72 | Y17: 72 | Z17: 72 | AA17: 72 | AB17: 72 | AC17: 96 | AD17: 96 | AE17: 96 | AF17: 96 | AG17: 96 | AH17: 108 | AI17: 108 | AJ17: 108 | AK17: 108 | AL17: 108 | AM17: 120 | AN17: 120 | AO17: 120 | AP17: 120 | AQ17: 120 | AR17: 120 | AS17: 120 | AT17: 120 | AU17: 120 | AV17: 120 | AW17: 120 | AX17: 120 | AY17: 120 | AZ17: 120 | BA17: 120 | BB17: 120 | BC17: 120 | BD17: 120 | BE17: 120 | BF17: 120 | BG17: 120 | BH17: 120 | BI17: 120 | BJ17: 120 | BK17: 120 | BL17: 120 | BM17: 120 | BN17: 120 | BO17: 120 | BP17: 120 | BQ17: 120 | BR17: 120 | BS17: 120 | BT17: 120 | BU17: 120 | BV17: 120 | BW17: 120 | BX17: 120 | BY17: 120

Sheet Cell 4 603
B4: Model 603 | AK4: Target : 120 Prs/H | BT4: Cell 4 | DH4: Target : 120 Prs/H
B6: Description | C6: Output | D6: Hari ke- | AK6: Day
D7: 1 | E7: 2 | F7: 3 | G7: 4 | H7: 5 | I7: =1+H7 -> 6 | J7: =1+I7 -> 7 | K7: =1+J7 -> 8 | L7: =1+K7 -> 9 | M7: =1+L7 -> 10 | N7: =1+M7 -> 11 | O7: =1+N7 -> 12 | P7: =1+O7 -> 13 | ... DK7: =1+DJ7 -> 112
D8: 46013 | E8: 46014 | F8: 46015 | G8: 46017 | H8: 46020 | I8: 46021 | J8: 46022 | K8: 46024 | L8: 46027 | M8: 46028 | N8: 46029 | O8: 46030 | P8: 46031 | Q8: 46034 | R8: 46035 | S8: 46036 | T8: 46037 | U8: 46039 | V8: 46041 | W8: 46042 | X8: 46043 | Y8: 46044 | Z8: 46045 | AA8: 46048 | AB8: 46049 | AC8: 46050 | AD8: 46051 | AE8: 46052 | AF8: 46055 | AG8: 46056 | AH8: 46057 | AI8: 46058 | AJ8: 46059 | AK8: 46062 | AL8: 46063 | AM8: 46064 | AN8: 46065 | AO8: 46066 | AP8: 46069 | AQ8: 46070 | AR8: 46071 | AS8: 46072 | AT8: 46073 | AU8: 46074 | AV8: 46076 | AW8: 46077 | AX8: 46078 | AY8: 46079 | AZ8: 46080 | BA8: 46081 | BB8: 46083 | BC8: 46084 | BD8: 46085 | BE8: 46086 | BF8: 46087 | BG8: 46090 | BH8: 46091 | BI8: 46092 | BJ8: 46093 | BK8: 46094 | BL8: 46097 | BM8: 46098 | BN8: 46099 | BO8: 46106 | BP8: 46107 | BQ8: 46108 | BR8: 46109 | BS8: 46111 | BT8: 46112 | BU8: 46113 | BV8: 46114 | BW8: 46115 | BX8: 46116 | BY8: 46118 | BZ8: 46119 | CA8: 46120 | CB8: 46121 | CC8: 46122 | CD8: 46123 | CE8: 46125 | CF8: 46126 | CG8: 46127 | CH8: 46128 | CI8: 46129 | CJ8: 46130 | CK8: 46132 | CL8: 46133 | CM8: 46134 | CN8: 46135 | CO8: 46136 | CP8: 46137 | CQ8: 46138 | CR8: 46139 | CS8: 46140 | CT8: 46141 | CU8: 46142 | CV8: 46143 | CW8: 46144 | CX8: 46145 | CY8: 46146 | CZ8: 46147 | DA8: 46148 | DB8: 46149 | DC8: 46150 | DD8: 46151 | DE8: 46152 | DF8: 46153 | DG8: 46154 | DH8: 46155 | DI8: 46156 | DJ8: 46157 | DK8: 46158
B9: Cutting+Prep | C9: Output/Day | D9: 468 | E9: 522 | F9: 300 | H9: 276 | I9: 540 | J9: 444 | K9: 462 | L9: 600 | M9: 582 | N9: 429 | AA9: 600 | AB9: 600 | AC9: 612 | AD9: 672 | AE9: 348 | AF9: 468 | AG9: 552 | AH9: 316 | AI9: 503 | AJ9: 690 | AK9: 438 | AL9: 552 | AM9: 636 | AN9: 754 | AO9: 800 | AP9: 984 | AQ9: 552 | AR9: 1152 | AS9: 1470 | AT9: 858 | AU9: 948 | AV9: 1498 | AW9: 1148 | AX9: 1134 | AY9: 1098 | AZ9: 0 | BA9: 582 | BB9: 1278 | BC9: 732 | BD9: 660 | BE9: 600 | BF9: 0 | BG9: 0 | BH9: 708 | BI9: 600 | BJ9: 630 | BK9: 864 | BL9: 702 | BM9: 408 | BN9: 630 | BO9: 708 | BP9: 714 | BQ9: 840 | BR9: 1091 | BS9: 1113 | BT9: 894 | BU9: 924 | BV9: 816 | BW9: 1188 | BX9: 1224 | BY9: 1160 | BZ9: 1626 | CA9: 1162 | CB9: 960 | CC9: 720 | CD9: 708 | CE9: 1200 | CF9: 1056 | CG9: 1200 | CH9: 1272 | CI9: 510 | CJ9: 1926 | CK9: 1782 | CL9: 1068
C10: Output/H | D10: =D9/8 -> 58.5 | E10: =E9/8 -> 65.25 | F10: =F9/10 -> 30 | G10: =G9/8 -> 0 | H10: =+H9/8 -> 34.5 | I10: =+I9/8 -> 67.5 | J10: =J9/10 -> 44.4 | K10: =K9/10 -> 46.2 | L10: =L9/10 -> 60 | M10: =M9/10 -> 58.2 | N10: =SUM(N9:N9)/8 -> 53.625 | O10: =O9/8 -> 0 | P10: =P9/8 -> 0 | Q10: =Q9/8 -> 0 | R10: =R9/8 -> 0 | S10: =S9/8 -> 0 | T10: =SUM(T9:T9)/8 -> 0 | U10: =SUM(U9:U9)/8 -> 0 | V10: =SUM(V9:V9)/8 -> 0 | W10: =SUM(W9:W9)/8 -> 0 | X10: =SUM(X9:X9)/8 -> 0 | Y10: =SUM(Y9:Y9)/8 -> 0 | Z10: =Z9/8 -> 0 | AA10: =AA9/8 -> 75 | AB10: =AB9/8 -> 75 | AC10: =AC9/10 -> 61.2 | AD10: =AD9/8 -> 84 | AE10: =+AE9/8 -> 43.5 | AF10: =+AF9/8 -> 58.5 | AG10: =AG9/9 -> 61.333333 | AH10: =AH9/8 -> 39.5 | AI10: =AI9/8 -> 62.875 | AJ10: =SUM(AJ9:AJ9)/8 -> 86.25 | AK10: =AK9/8 -> 54.75 | AL10: =AL9/8 -> 69 | AM10: =AM9/8 -> 79.5 | AN10: =AN9/8 -> 94.25 | AO10: =AO9/8 -> 100 | AP10: =AP9/9 -> 109.33333 | AQ10: =AQ9/5 -> 110.4 | AR10: =AR9/9 -> 128 | AS10: =AS9/10 -> 147 | AT10: =AT9/8 -> 107.25 | AU10: =AU9/7 -> 135.42857 | AV10: =AV9/9 -> 166.44444 | AW10: =AW9/9 -> 127.55556 | AX10: =AX9/9 -> 126 | AY10: =AY9/9 -> 122 | AZ10: =AZ9/8 -> 0 | BA10: =BA9/5 -> 116.4 | BB10: =BB9/8 -> 159.75 | BC10: =BC9/8 -> 91.5 | BD10: =BD9/8 -> 82.5 | BE10: =BE9/8 -> 75 | BF10: =BF9/8 -> 0 | BG10: =BG9/8 -> 0 | BH10: =BH9/8 -> 88.5 | BI10: =BI9/8 -> 75 | ... BM10: =BM9/8 -> 51 | BN10: =BN9/9 -> 70 | BO10: =BO9/9 -> 78.666667 | BP10: =BP9/9 -> 79.333333 | BQ10: =BQ9/9 -> 93.333333 | BR10: =BR9/7 -> 155.85714 | BS10: =BS9/10 -> 111.3 | BT10: =BT9/10 -> 89.4 | BU10: =BU9/10 -> 92.4 | BV10: =BV9/10 -> 81.6 | BW10: =BW9/10 -> 118.8 | BX10: =BX9/10 -> 122.4 | BY10: =BY9/10 -> 116 | BZ10: =BZ9/12 -> 135.5 | CA10: =CA9/12 -> 96.833333 | CB10: =CB9/12 -> 80 | CC10: =CC9/12 -> 60 | CD10: =CD9/8 -> 88.5 | CE10: =CE9/11 -> 109.09091 | CF10: =CF9/11 -> 96 | CG10: =CG9/11 -> 109.09091 | CH10: =CH9/11 -> 115.63636 | CI10: =CI9/11 -> 46.363636 | CJ10: =CJ9/11 -> 175.09091 | CK10: =CK9/11 -> 162 | CL10: =CL9/12 -> 89 | CM10: =CM9/12 -> 0 | CN10: =CN9/12 -> 0 | CO10: =CO9/12 -> 0 | CP10: =CP9/12 -> 0 | CQ10: =CQ9/12 -> 0 | CR10: =CR9/12 -> 0 | CS10: =CS9/12 -> 0 | ... DJ10: =DJ9/12 -> 0 | DK10: =DK9/10 -> 0
B11: Comshare | C11: =C9 -> Output/Day | D11: 126 | E11: 150 | F11: 144 | H11: 222 | I11: 246 | J11: 216 | K11: 246 | L11: 246 | M11: 288 | N11: 342 | AA11: 528 | AB11: 566 | AC11: 467 | AD11: 442 | AE11: 449 | AF11: 583 | AG11: 692 | AH11: 714 | AI11: 774 | AJ11: 798 | AK11: 408 | AL11: 558 | AM11: 600 | AN11: 870 | AO11: 719 | AP11: 697 | AQ11: 623 | AR11: 767 | AS11: 676 | AT11: 702 | AU11: 420 | AV11: 490 | AW11: 642 | AX11: 621 | AY11: =789-55 -> 734 | AZ11: 733 | BA11: 384 | BB11: 510 | BC11: 612 | BD11: 580 | BE11: 568 | BF11: 568 | BG11: 480 | BH11: 516 | BI11: 600 | BJ11: 598 | BK11: 651 | BL11: 606 | BM11: 639 | BN11: 504 | BO11: 582 | BP11: 636 | BQ11: 630 | BR11: 732 | BS11: 815 | BT11: 798 | BU11: 732 | BV11: 696 | BW11: 726 | BX11: 750 | BY11: 753 | BZ11: 636 | CA11: 609 | CB11: 732 | CC11: 736 | CD11: 696 | CE11: 743 | CF11: 710 | CG11: 804 | CH11: 726 | CI11: 774 | CJ11: 696 | CK11: 892 | CL11: 916
C12: Output/H | D12: =D11/9 -> 14 | E12: =E11/9 -> 16.666667 | F12: =F11/10 -> 14.4 | G12: =G11/9 -> 0 | H12: =+H11/9 -> 24.666667 | I12: =+I11/9 -> 27.333333 | J12: =J11/10 -> 21.6 | K12: =K11/10 -> 24.6 | L12: =L11/10 -> 24.6 | M12: =M11/10 -> 28.8 | N12: =SUM(N11:N11)/8 -> 42.75 | O12: =O11/8 -> 0 | P12: =P11/8 -> 0 | Q12: =Q11/8 -> 0 | R12: =R11/8 -> 0 | S12: =S11/8 -> 0 | T12: =SUM(T11:T11)/8 -> 0 | U12: =SUM(U11:U11)/8 -> 0 | V12: =SUM(V11:V11)/8 -> 0 | W12: =SUM(W11:W11)/8 -> 0 | X12: =SUM(X11:X11)/8 -> 0 | Y12: =SUM(Y11:Y11)/8 -> 0 | Z12: =Z11/9 -> 0 | AA12: =AA11/9 -> 58.666667 | AB12: =AB11/9 -> 62.888889 | AC12: =AC11/10 -> 46.7 | AD12: =AD11/9 -> 49.111111 | AE12: =+AE11/9 -> 49.888889 | AF12: =+AF11/9 -> 64.777778 | AG12: =AG11/9 -> 76.888889 | AH12: =AH11/9 -> 79.333333 | AI12: =AI11/9 -> 86 | AJ12: =AJ11/9 -> 88.666667 | AK12: =AK11/9 -> 45.333333 | AL12: =AL11/10 -> 55.8 | AM12: =AM11/9 -> 66.666667 | AN12: =AN11/10 -> 87 | AO12: =AO11/9 -> 79.888889 | AP12: =AP11/9 -> 77.444444 | AQ12: =AQ11/7 -> 89 | AR12: =AR11/10 -> 76.7 | AS12: =AS11/10 -> 67.6 | AT12: =AT11/9 -> 78 | AU12: =AU11/7 -> 60 | AV12: =AV11/10 -> 49 | AW12: =AW11/10 -> 64.2 | AX12: =AX11/10 -> 62.1 | AY12: =AY11/10 -> 73.4 | AZ12: =AZ11/10 -> 73.3 | BA12: =BA11/7 -> 54.857143 | BB12: =BB11/10 -> 51 | BC12: =BC11/10 -> 61.2 | BD12: =BD11/10 -> 58 | BE12: =BE11/10 -> 56.8 | BF12: =BF11/10 -> 56.8 | BG12: =BG11/10 -> 48 | BH12: =BH11/10 -> 51.6 | BI12: =BI11/10 -> 60 | BJ12: =+BJ11/10 -> 59.8 | BK12: =+BK11/10 -> 65.1 | BL12: =+BL11/10 -> 60.6 | BM12: =+BM11/10 -> 63.9 | BN12: =+BN11/10 -> 50.4 | BO12: =+BO11/10 -> 58.2 | BP12: =+BP11/10 -> 63.6 | BQ12: =+BQ11/10 -> 63 | BR12: =+BR11/10 -> 73.2 | BS12: =+BS11/11 -> 74.090909 | BT12: =+BT11/11 -> 72.545455 | BU12: =+BU11/12 -> 61 | BV12: =+BV11/12 -> 58 | BW12: =+BW11/12 -> 60.5 | BX12: =+BX11/12 -> 62.5 | BY12: =+BY11/12 -> 62.75 | BZ12: =+BZ11/12 -> 53 | CA12: =+CA11/12 -> 50.75 | CB12: =+CB11/12 -> 61 | CC12: =+CC11/12 -> 61.333333 | CD12: =+CD11/10 -> 69.6 | CE12: =+CE11/12 -> 61.916667 | CF12: =+CF11/12 -> 59.166667 | CG12: =+CG11/12 -> 67 | CH12: =+CH11/12 -> 60.5 | CI12: =+CI11/12 -> 64.5 | CJ12: =+CJ11/12 -> 58 | CK12: =+CK11/12 -> 74.333333 | CL12: =+CL11/12 -> 76.333333 | ... DK12: =+DK11/12 -> 0
